<?xml version="1.0"?>
<sdf version='1.6'>
  <model name='luffy'>
    <link name='base_link'>
      <pose frame=''>0 0 0 0 -0 0</pose>
      <inertial>
        <pose frame=''>1e-06 -0 -0.000651 0 -0 0</pose>
        <mass>0.510673</mass>
        <inertia>
          <ixx>0.000722388</ixx>
          <ixy>1.63791e-24</ixy>
          <ixz>-5.50202e-07</ixz>
          <iyy>0.00158624</iyy>
          <iyz>-1.38686e-13</iyz>
          <izz>0.00223359</izz>
        </inertia>
      </inertial>
      <collision name='base_link_collision'>
        <pose frame=''>0 0 0 0 -0 0</pose>
        <geometry>
          <box>
            <size>0.2 0.2 0.08</size>
          </box>
        </geometry>
        <surface>
          <contact>
            <ode/>
          </contact>
          <friction>
            <ode>
              <mu>0</mu>
              <mu2>0</mu2>
            </ode>
          </friction>
        </surface>
      </collision>
      <collision name='base_link_collision_1'>
        <pose frame=''>0.08 0 -0.04 0 -0 0</pose>
        <geometry>
          <sphere>
            <radius>0.01</radius>
          </sphere>
        </geometry>
        <surface>
          <contact>
            <ode/>
          </contact>
          <friction>
            <ode>
              <mu>0</mu>
              <mu2>0</mu2>
            </ode>
          </friction>
        </surface>
      </collision>

      <visual name='base_link_visual'>
        <pose frame=''>0 0 0 0 -0 0</pose>
        <geometry>
          <box>
            <size>0.2 0.2 0.08</size>
          </box>
        </geometry>
        <material>
          <script>
            <name>Gazebo/Orange</name>
            <uri>file://media/materials/scripts/gazebo.material</uri>
          </script>
        </material>
      </visual>
      <visual name='base_link_fixed_joint_lump__caster_visual_1'>
        <pose frame=''>0.08 0 -0.04 0 -0 0</pose>
        <geometry>
          <sphere>
            <radius>0.01</radius>
          </sphere>
        </geometry>
      </visual>
      <velocity_decay/>
      <gravity>1</gravity>
      <velocity_decay/>
      <sensor name='frontLeftCamera' type='camera'>
        <update_rate>0.4</update_rate>
        <camera name='frontLeftCamera'>
          <horizontal_fov>1.5708</horizontal_fov>
          <image>
            <width>1280</width>
            <height>720</height>
            <format>R8G8B8</format>
          </image>
          <clip>
            <near>0.01</near>
            <far>100</far>
          </clip>
          <noise>
            <type>gaussian</type>
            <mean>0</mean>
            <stddev>0</stddev>
          </noise>
        </camera>
        <plugin name='camera_plugin' filename='libgazebo_ros_camera.so'>
          <alwaysOn>1</alwaysOn>
          <updateRate>0.4</updateRate>
          <cameraName>sensors/frontLeftCamera</cameraName>
          <imageTopicName>image</imageTopicName>
          <cameraInfoTopicName>info</cameraInfoTopicName>
          <frameName>frontLeftCamera</frameName>
        </plugin>
        <pose>-0.25 -0.05 0.1 0 -0 3.14159</pose>
      </sensor>
      <sensor name='frontRightCamera' type='camera'>
        <update_rate>0.4</update_rate>
        <camera name='frontRightCamera'>
          <horizontal_fov>1.5708</horizontal_fov>
          <image>
            <width>1280</width>
            <height>720</height>
            <format>R8G8B8</format>
          </image>
          <clip>
            <near>0.01</near>
            <far>100</far>
          </clip>
          <noise>
            <type>gaussian</type>
            <mean>0</mean>
            <stddev>0</stddev>
          </noise>
        </camera>
        <plugin name='camera_plugin' filename='libgazebo_ros_camera.so'>
          <alwaysOn>1</alwaysOn>
          <updateRate>0.4</updateRate>
          <cameraName>sensors/frontRightCamera</cameraName>
          <imageTopicName>image</imageTopicName>
          <cameraInfoTopicName>info</cameraInfoTopicName>
          <frameName>frontRightCamera</frameName>
        </plugin>
        <pose>-0.25 0.05 0.1 0 -0 3.14159</pose>
      </sensor>
      <sensor name='frontUltrasonic' type='ray'>
        <update_rate>1</update_rate>
        <visualize>1</visualize>
        <ray>
          <scan>
            <horizontal>
              <samples>10</samples>
              <resolution>1</resolution>
              <min_angle>-0.05</min_angle>
              <max_angle>0.05</max_angle>
            </horizontal>
          </scan>
          <range>
            <min>0.02</min>
            <max>6</max>
            <resolution>0.03</resolution>
          </range>
        </ray>
        <plugin name='ultrasonic_plugin' filename='libgazebo_ros_range.so'>
          <gaussianNoise>0.0</gaussianNoise>
          <alwaysOn>1</alwaysOn>
          <updateRate>1</updateRate>
          <topicName>sensors/frontUltrasonic</topicName>
          <frameName>frontUltrasonic</frameName>
          <radiation>ultrasound</radiation>
          <fov>0.05--0.05</fov>
          <visualize>1</visualize>
        </plugin>
        <pose>-0.13 0 0 0 -0 3.14159</pose>
      </sensor>
      <sensor name='leftUltrasonic' type='ray'>
        <update_rate>1</update_rate>
        <visualize>1</visualize>
        <ray>
          <scan>
            <horizontal>
              <samples>10</samples>
              <resolution>1</resolution>
              <min_angle>-0.05</min_angle>
              <max_angle>0.05</max_angle>
            </horizontal>
          </scan>
          <range>
            <min>0.02</min>
            <max>6</max>
            <resolution>0.03</resolution>
          </range>
        </ray>
        <plugin name='ultrasonic_plugin' filename='libgazebo_ros_range.so'>
          <gaussianNoise>0.0</gaussianNoise>
          <alwaysOn>1</alwaysOn>
          <updateRate>1</updateRate>
          <topicName>sensors/leftUltrasonic</topicName>
          <frameName>leftUltrasonic</frameName>
          <radiation>ultrasound</radiation>
          <fov>0.05--0.05</fov>
          <visualize>1</visualize>
        </plugin>
        <pose>-0.13 -0.075 0 0 -0 2.61799</pose>
      </sensor>
      <sensor name='rightUltrasonic' type='ray'>
        <update_rate>1</update_rate>
        <visualize>1</visualize>
        <ray>
          <scan>
            <horizontal>
              <samples>10</samples>
              <resolution>1</resolution>
              <min_angle>-0.05</min_angle>
              <max_angle>0.05</max_angle>
            </horizontal>
          </scan>
          <range>
            <min>0.02</min>
            <max>6</max>
            <resolution>0.03</resolution>
          </range>
        </ray>
        <plugin name='ultrasonic_plugin' filename='libgazebo_ros_range.so'>
          <gaussianNoise>0.0</gaussianNoise>
          <alwaysOn>1</alwaysOn>
          <updateRate>1</updateRate>
          <topicName>sensors/rightUltrasonic</topicName>
          <frameName>rightUltrasonic</frameName>
          <radiation>ultrasound</radiation>
          <fov>0.05--0.05</fov>
          <visualize>1</visualize>
        </plugin>
        <pose>-0.13 0.075 0 0 0 -2.61799</pose>
      </sensor>
      <sensor name='visualCamera' type='camera'>
        <update_rate>15</update_rate>
        <camera name='visualCamera'>
          <horizontal_fov>1.75</horizontal_fov>
          <image>
            <width>1280</width>
            <height>720</height>
            <format>R8G8B8</format>
          </image>
          <clip>
            <near>0.001</near>
            <far>100</far>
          </clip>
          <noise>
            <type>gaussian</type>
            <mean>0</mean>
            <stddev>0</stddev>
          </noise>
        </camera>
        <plugin name='camera_plugin' filename='libgazebo_ros_camera.so'>
          <alwaysOn>1</alwaysOn>
          <updateRate>15</updateRate>
          <cameraName>sensors/visualCamera</cameraName>
          <imageTopicName>image</imageTopicName>
          <cameraInfoTopicName>info</cameraInfoTopicName>
          <frameName>visualCamera</frameName>
        </plugin>
        <pose>1.2 0 0.5 0 0.2 -3.13319</pose>
      </sensor>
    </link>
    <link name='left_wheel'>
      <pose frame=''>-0.09 0.105 0 0 -0 0</pose>
      <inertial>
        <pose frame=''>0 0 0 0 -0 0</pose>
        <mass>0.00333333</mass>
        <inertia>
          <ixx>4.16667e-06</ixx>
          <ixy>0</ixy>
          <ixz>0</ixz>
          <iyy>2.16049e-06</iyy>
          <iyz>0</iyz>
          <izz>2.16049e-06</izz>
        </inertia>
      </inertial>
      <collision name='left_wheel_collision'>
        <pose frame=''>0 0 0 1.57079 -0 0</pose>
        <geometry>
          <cylinder>
            <length>0.01</length>
            <radius>0.05</radius>
          </cylinder>
        </geometry>
        <surface>
          <contact>
            <ode/>
          </contact>
          <friction>
            <ode>
              <mu>1</mu>
              <mu2>1</mu2>
            </ode>
          </friction>
        </surface>
      </collision>
      <visual name='left_wheel_visual'>
        <pose frame=''>0 0 0 1.57079 -0 0</pose>
        <geometry>
          <cylinder>
            <length>0.01</length>
            <radius>0.05</radius>
          </cylinder>
        </geometry>
        <material>
          <script>
            <name>Gazebo/Blue</name>
            <uri>file://media/materials/scripts/gazebo.material</uri>
          </script>
        </material>
      </visual>
      <gravity>1</gravity>
      <velocity_decay/>
    </link>
    <joint name='left_wheel_joint' type='revolute'>
      <child>left_wheel</child>
      <parent>base_link</parent>
      <axis>
        <xyz>0 1 0</xyz>
        <limit>
          <effort>50</effort>
          <velocity>50</velocity>
          <lower>-1e+16</lower>
          <upper>1e+16</upper>
        </limit>
        <dynamics>
          <damping>0.1</damping>
          <friction>0.1</friction>
          <spring_reference>0</spring_reference>
          <spring_stiffness>0</spring_stiffness>
        </dynamics>
        <use_parent_model_frame>0</use_parent_model_frame>
      </axis>
    </joint>

    <link name='right_wheel'>
      <pose frame=''>-0.09 -0.105 0 0 -0 0</pose>
      <inertial>
        <pose frame=''>0 0 0 0 -0 0</pose>
        <mass>0.00333333</mass>
        <inertia>
          <ixx>4.16667e-06</ixx>
          <ixy>0</ixy>
          <ixz>0</ixz>
          <iyy>2.16049e-06</iyy>
          <iyz>0</iyz>
          <izz>2.16049e-06</izz>
        </inertia>
      </inertial>
      <collision name='right_wheel_collision'>
        <pose frame=''>0 0 0 1.57079 -0 0</pose>
        <geometry>
          <cylinder>
            <length>0.01</length>
            <radius>0.05</radius>
          </cylinder>
        </geometry>
        <surface>
          <contact>
            <ode/>
          </contact>
          <friction>
            <ode>
              <mu>1</mu>
              <mu2>1</mu2>
            </ode>
          </friction>
        </surface>
      </collision>
      <visual name='right_wheel_visual'>
        <pose frame=''>0 0 0 1.57079 -0 0</pose>
        <geometry>
          <cylinder>
            <length>0.01</length>
            <radius>0.05</radius>
          </cylinder>
        </geometry>
        <material>
          <script>
            <name>Gazebo/Blue</name>
            <uri>file://media/materials/scripts/gazebo.material</uri>
          </script>
        </material>
      </visual>
      <gravity>1</gravity>
      <velocity_decay/>
    </link>
    <joint name='right_wheel_joint' type='revolute'>
      <child>right_wheel</child>
      <parent>base_link</parent>
      <axis>
        <xyz>0 1 0</xyz>
        <limit>
          <effort>50</effort>
          <velocity>50</velocity>
          <lower>-1e+16</lower>
          <upper>1e+16</upper>
        </limit>
        <dynamics>
          <damping>0.1</damping>
          <friction>0.1</friction>
          <spring_reference>0</spring_reference>
          <spring_stiffness>0</spring_stiffness>
        </dynamics>
        <use_parent_model_frame>0</use_parent_model_frame>
      </axis>
    </joint>


    <link name='left_wheel2'>
      <pose frame=''>0.09 0.105 0 0 -0 0</pose>
      <inertial>
        <pose frame=''>0 0 0 0 -0 0</pose>
        <mass>0.00333333</mass>
        <inertia>
          <ixx>4.16667e-06</ixx>
          <ixy>0</ixy>
          <ixz>0</ixz>
          <iyy>2.16049e-06</iyy>
          <iyz>0</iyz>
          <izz>2.16049e-06</izz>
        </inertia>
      </inertial>
      <collision name='left_wheel_collision2'>
        <pose frame=''>0 0 0 1.57079 -0 0</pose>
        <geometry>
          <cylinder>
            <length>0.01</length>
            <radius>0.05</radius>
          </cylinder>
        </geometry>
        <surface>
          <contact>
            <ode/>
          </contact>
          <friction>
            <ode>
              <mu>1</mu>
              <mu2>1</mu2>
            </ode>
          </friction>
        </surface>
      </collision>
      <visual name='left_wheel_visual2'>
        <pose frame=''>0 0 0 1.57079 -0 0</pose>
        <geometry>
          <cylinder>
            <length>0.01</length>
            <radius>0.05</radius>
          </cylinder>
        </geometry>
        <material>
          <script>
            <name>Gazebo/White</name>
            <uri>file://media/materials/scripts/gazebo.material</uri>
          </script>
        </material>
      </visual>
      <gravity>1</gravity>
      <velocity_decay/>
    </link>
    <joint name='left_wheel_joint2' type='revolute'>
      <child>left_wheel2</child>
      <parent>base_link</parent>
      <axis>
        <xyz>0 1 0</xyz>
        <limit>
          <effort>50</effort>
          <velocity>50</velocity>
          <lower>-1e+16</lower>
          <upper>1e+16</upper>
        </limit>
        <dynamics>
          <damping>0.1</damping>
          <friction>0.1</friction>
          <spring_reference>0</spring_reference>
          <spring_stiffness>0</spring_stiffness>
        </dynamics>
        <use_parent_model_frame>0</use_parent_model_frame>
      </axis>
    </joint>

    <link name='right_wheel2'>
      <pose frame=''>0.09 -0.105 0 0 -0 0</pose>
      <inertial>
        <pose frame=''>0 0 0 0 -0 0</pose>
        <mass>0.00333333</mass>
        <inertia>
          <ixx>4.16667e-06</ixx>
          <ixy>0</ixy>
          <ixz>0</ixz>
          <iyy>2.16049e-06</iyy>
          <iyz>0</iyz>
          <izz>2.16049e-06</izz>
        </inertia>
      </inertial>
      <collision name='right_wheel_collision2'>
        <pose frame=''>0 0 0 1.57079 -0 0</pose>
        <geometry>
          <cylinder>
            <length>0.01</length>
            <radius>0.05</radius>
          </cylinder>
        </geometry>
        <surface>
          <contact>
            <ode/>
          </contact>
          <friction>
            <ode>
              <mu>1</mu>
              <mu2>1</mu2>
            </ode>
          </friction>
        </surface>
      </collision>
      <visual name='right_wheel_visual2'>
        <pose frame=''>0 0 0 1.57079 -0 0</pose>
        <geometry>
          <cylinder>
            <length>0.01</length>
            <radius>0.05</radius>
          </cylinder>
        </geometry>
        <material>
          <script>
            <name>Gazebo/White</name>
            <uri>file://media/materials/scripts/gazebo.material</uri>
          </script>
        </material>
      </visual>
      <gravity>1</gravity>
      <velocity_decay/>
    </link>
    <joint name='right_wheel_joint2' type='revolute'>
      <child>right_wheel2</child>
      <parent>base_link</parent>
      <axis>
        <xyz>0 1 0</xyz>
        <limit>
          <effort>50</effort>
          <velocity>50</velocity>
          <lower>-1e+16</lower>
          <upper>1e+16</upper>
        </limit>
        <dynamics>
          <damping>0.1</damping>
          <friction>0.1</friction>
          <spring_reference>0</spring_reference>
          <spring_stiffness>0</spring_stiffness>
        </dynamics>
        <use_parent_model_frame>0</use_parent_model_frame>
      </axis>
    </joint>


    <!-- <static>0</static> -->
    <!-- <plugin name='gazebo_ros_control' filename='libgazebo_ros_control.so'>
      <robotNamespace/>
      <robotSimType>gazebo_ros_control/DefaultRobotHWSim</robotSimType>
    </plugin> Don't uncomment, it causes gazebo to get stuck-->

    <plugin name='skid_steer_drive_controller' filename='libgazebo_ros_skid_steer_drive.so'>
      <updateRate>100</updateRate>
      <robotNamespace>control/ground</robotNamespace>
      <leftFrontJoint>left_wheel_joint</leftFrontJoint>
      <rightFrontJoint>right_wheel_joint</rightFrontJoint>
      <leftRearJoint>left_wheel_joint2</leftRearJoint>
      <rightRearJoint>right_wheel_joint2</rightRearJoint>
      <wheelSeparation>0.16666666666666669</wheelSeparation>
      <wheelDiameter>0.1</wheelDiameter>
      <robotBaseFrame>base_link</robotBaseFrame>
      <torque>50</torque>
      <broadcastTF>1</broadcastTF>
      <commandTopic>cmd</commandTopic>
      <odometryTopic>odom</odometryTopic>
      <odometryFrame>odom</odometryFrame>
      <covariance_x>0.0001</covariance_x>
      <covariance_y>0.0001</covariance_y>
      <covariance_yaw>0.0001</covariance_yaw>
    </plugin>
    <include>
      <uri>model://iris</uri>
      <pose>0 0 0.08 0 0 0</pose>
    </include>

    <joint name='luffy_iris_joint' type='fixed'>
      <parent>base_link</parent>
      <child>iris::base_link</child>
      <pose>0 0 0 0 0 0</pose>
      <physics>
        <ode>
          <limit>
            <cfm>0</cfm>
            <erp>0.2</erp>
          </limit>
          <suspension>
            <cfm>0</cfm>
            <erp>0.2</erp>
          </suspension>
        </ode>
      </physics>
    </joint>

    <frame name='FrontLeftCamera2GroundCore' attached_to='frame_link'>
      <pose>-0.25 -0.05 0.1 0 -0 3.14159</pose>
    </frame>
    <frame name='frontLeftCamera' attached_to='FrontLeftCamera2GroundCore'/>
    <frame name='FrontRightCamera2GroundCore' attached_to='frame_link'>
      <pose>-0.25 0.05 0.1 0 -0 3.14159</pose>
    </frame>
    <frame name='frontRightCamera' attached_to='FrontRightCamera2GroundCore'/>
    <frame name='FrontUltrasonic2GroundCore' attached_to='frame_link'>
      <pose>-0.13 0 0 0 -0 3.14159</pose>
    </frame>
    <frame name='frontUltrasonic' attached_to='FrontUltrasonic2GroundCore'/>
    <frame name='LeftUltrasonic2GroundCore' attached_to='frame_link'>
      <pose>-0.13 -0.075 0 0 -0 2.61799</pose>
    </frame>
    <frame name='leftUltrasonic' attached_to='LeftUltrasonic2GroundCore'/>
    <frame name='RightUltrasonic2GroundCore' attached_to='frame_link'>
      <pose>-0.13 0.075 0 0 -0 -2.618</pose>
    </frame>
    <frame name='rightUltrasonic' attached_to='RightUltrasonic2GroundCore'/>
    <!-- <frame name='axle_leftFront_joint' attached_to='frame_link'>
      <pose>0.07 0.05 -0.05 1.5708 -0 0</pose>
    </frame>
    <frame name='axle_leftFront_link' attached_to='axle_leftFront_joint'/>
    <frame name='axle_leftRear_joint' attached_to='frame_link'>
      <pose>-0.07 0.05 -0.05 1.5708 -0 0</pose>
    </frame>
    <frame name='axle_leftRear_link' attached_to='axle_leftRear_joint'/>
    <frame name='axle_rightFront_joint' attached_to='frame_link'>
      <pose>0.07 -0.05 -0.05 1.5708 -0 0</pose>
    </frame>
    <frame name='axle_rightFront_link' attached_to='axle_rightFront_joint'/>
    <frame name='axle_rightRear_joint' attached_to='frame_link'>
      <pose>-0.07 -0.05 -0.05 1.5708 -0 0</pose>
    </frame>
    <frame name='axle_rightRear_link' attached_to='axle_rightRear_joint'/>
    <frame name='stator_leftFront_joint' attached_to='frame_link'>
      <pose>0.2 0.2 0 0 -0 0</pose>
    </frame>
    <frame name='stator_leftFront_link' attached_to='stator_leftFront_joint'/>
    <frame name='stator_leftRear_joint' attached_to='frame_link'>
      <pose>-0.2 0.2 0 0 -0 0</pose>
    </frame>
    <frame name='stator_leftRear_link' attached_to='stator_leftRear_joint'/>
    <frame name='stator_rightFront_joint' attached_to='frame_link'>
      <pose>0.2 -0.2 0 0 -0 0</pose>
    </frame>
    <frame name='stator_rightFront_link' attached_to='stator_rightFront_joint'/>
    <frame name='stator_rightRear_joint' attached_to='frame_link'>
      <pose>-0.2 -0.2 0 0 -0 0</pose>
    </frame>
    <frame name='stator_rightRear_link' attached_to='stator_rightRear_joint'/> -->
    <frame name='visualCamera_joint' attached_to='frame_link'>
      <pose>1.2 0 0.5 0 0.2 -3.13319</pose>
    </frame>
    <frame name='visualCamera' attached_to='visualCamera_joint'/>
    <frame name='frame_joint' attached_to='base_link'>
      <pose>0 0 0 0 -0 0</pose>
    </frame>
    <frame name='frame_link' attached_to='frame_joint'/>
  </model>
</sdf>
