<?xml version="1.0" ?>
<!-- =================================================================================== -->
<!-- |    This document was autogenerated by xacro from main.xml                       | -->
<!-- |    EDITING THIS FILE BY HAND IS NOT RECOMMENDED                                 | -->
<!-- =================================================================================== -->
<!-- ############################################################################ 
     ###################### Self-Driving Simulator - ARAV ####################### 
     ############################################################################
     #################### Author : Alberto Ceballos Gonzalez #################### 
     ######## E-mail : alberto.ceballos-gonzalez@student.isae-supaero.fr ######## 
     ######### (c) Copyright 2021. Alberto Ceballos. All Rights Reserved ########  
     ############################################################################ -->
<!-- ############################################################################

     This document contains the general description of the vehicle:
     
     	1. Include other documents:
     		- macros
     		- parameters
     		- control
     		- aerodynamics
     		- sensors
     		- visual (client for Gazebo)
     	2. Robot definition (frame + wheels + motors)
     	
     ############################################################################ -->
<robot name="arav">
  <!-- 1. INCLUDE FILES -->
  <!-- 1. INERTIA MACROS -->
  <!-- 1.1 3D inertia tensor of a cylinder -->
  <!-- 1.2 3D inertia tensor of a box -->
  <!-- 1.3 Null inertia -->
  <!-- 2. FRAME MACRO -->
  <!-- 3. WHEEL MACRO -->
  <!-- 4. MOTOR MACRO -->
  <!-- 1. FRAME -->
  <!-- 2. WHEELS -->
  <!-- 3. MOTORS -->
  <!-- 4. GENERAL DYNAMICS -->
  <!-- 5. ANGLES -->
  <!-- 6. CONTROL -->
  <!-- 7. AERODYNAMICS -->
  <!-- 8. CAMERAS -->
  <!-- 9. ULTRASONIC SENSORS -->
  <!-- 1. GROUND MODULE CONTROLLER -->
  <gazebo>
    <plugin filename="libgazebo_ros_skid_steer_drive.so" name="skid_steer_drive_controller">
      <updateRate>100</updateRate>
      <!-- Plugin update rate in Hz -->
      <robotNamespace>control/ground</robotNamespace>
      <!-- Robot name -->
      <leftFrontJoint>tire_rightFront_joint</leftFrontJoint>
      <!-- Name of left front joint -->
      <rightFrontJoint>tire_leftFront_joint</rightFrontJoint>
      <!-- Name of right front joint -->
      <leftRearJoint>tire_rightRear_joint</leftRearJoint>
      <!-- Name of left rear joint -->
      <rightRearJoint>tire_leftRear_joint</rightRearJoint>
      <!-- Name of right rear joint -->
      <wheelSeparation>0.16666666666666669</wheelSeparation>
      <!-- The distance from the center of one wheel to the other -->
      <wheelDiameter>0.1</wheelDiameter>
      <!-- Diameter of the wheels -->
      <robotBaseFrame>base_link</robotBaseFrame>
      <!-- Robot frame to calculate odometry from -->
      <torque>50</torque>
      <!-- Maximum torque which the wheels can produce -->
      <broadcastTF>true</broadcastTF>
      <!-- Set to true to publish transforms for the wheel links -->
      <commandTopic>cmd</commandTopic>
      <!-- Topic to receive geometry_msgs/Twist message commands -->
      <odometryTopic>odom</odometryTopic>
      <!-- Topic to publish nav_msgs/Odometry messages -->
      <odometryFrame>odom</odometryFrame>
      <!-- Odometry frame -->
      <covariance_x>0.0001</covariance_x>
      <!-- Default X covariance -->
      <covariance_y>0.0001</covariance_y>
      <!-- Default Y covariance -->
      <covariance_yaw>0.0001</covariance_yaw>
      <!-- Default Yaw covariance -->
    </plugin>
    <!-- 2. AERIAL MODULE CONTROLLER -->
    <plugin filename="libgazebo_ros_control.so" name="gazebo_ros_control">
      <robotNameSpace>/control/air</robotNameSpace>
      <robotSimType>gazebo_ros_control/DefaultRobotHWSim</robotSimType>
    </plugin>
  </gazebo>
  <!-- 1. AERODYNAMICS MACRO -->
  <!-- 2. IMPLEMENTATION -->
  <!-- 2 Propellers per rotor -->
  <!-- Propeller 1 -->
  <gazebo>
    <plugin filename="libLiftDragPlugin.so" name="aerodynamics_1_rightFront_plugin">
      <link_name>propeller_1_rightFront_link</link_name>
      <!-- Name of the link affected by the group of lift/drag properties -->
      <air_density>1.225</air_density>
      <!-- Density of the fluid this model is suspended in -->
      <area>1.0</area>
      <!-- Surface area of the link -->
      <a0>0.1</a0>
      <!-- The initial "alpha" or initial angle of attack -->
      <cla>0.1</cla>
      <!-- The ratio of the coefficient of lift and alpha slope before stall -->
      <cda>0.01</cda>
      <!-- The ratio of the coefficient of drag and alpha slope before stall -->
      <cma>0.0</cma>
      <!-- The ratio of the coefficient of momentum and alpha slope before stall -->
      <cp>0 -0.11375 0</cp>
      <!-- Center of pressure -->
      <forward>1 0 0</forward>
      <!-- 3-vector representing the forward direction of motion in the link frame (-Y AXIS) -->
      <upward>0 0 1</upward>
      <!-- 3-vector representing the direction of lift or drag (Z AXIS) -->
      <alpha_stall>0.2</alpha_stall>
      <!-- Angle of attack at stall point; the peak angle of attack -->
      <cla_stall>-0.2</cla_stall>
      <!-- The ratio of coefficient of lift and alpha slope after stall -->
      <cda_stall>1.0</cda_stall>
      <!-- The ratio of coefficient of drag and alpha slope after stall -->
      <cma_stall>0.0</cma_stall>
    </plugin>
  </gazebo>
  <!-- Propeller 2 -->
  <gazebo>
    <plugin filename="libLiftDragPlugin.so" name="aerodynamics_2_rightFront_plugin">
      <link_name>propeller_2_rightFront_link</link_name>
      <!-- Name of the link affected by the group of lift/drag properties -->
      <air_density>1.225</air_density>
      <!-- Density of the fluid this model is suspended in -->
      <area>1.0</area>
      <!-- Surface area of the link -->
      <a0>0.1</a0>
      <!-- The initial "alpha" or initial angle of attack -->
      <cla>0.1</cla>
      <!-- The ratio of the coefficient of lift and alpha slope before stall -->
      <cda>0.01</cda>
      <!-- The ratio of the coefficient of drag and alpha slope before stall -->
      <cma>0.0</cma>
      <!-- The ratio of the coefficient of momentum and alpha slope before stall -->
      <cp>0 0.11375 0</cp>
      <!-- Center of pressure. The forces due to lift and drag will be applied here (GC) -->
      <forward>-1 0 0</forward>
      <!-- 3-vector representing the forward direction of motion in the link frame (+Y AXIS) -->
      <upward>0 0 1</upward>
      <!-- 3-vector representing the direction of lift or drag (Z AXIS) -->
      <alpha_stall>0.2</alpha_stall>
      <!-- Angle of attack at stall point; the peak angle of attack -->
      <cla_stall>-0.2</cla_stall>
      <!-- The ratio of coefficient of lift and alpha slope after stall -->
      <cda_stall>1.0</cda_stall>
      <!-- The ratio of coefficient of drag and alpha slope after stall -->
      <cma_stall>0.0</cma_stall>
    </plugin>
  </gazebo>
  <!-- 2 Propellers per rotor -->
  <!-- Propeller 1 -->
  <gazebo>
    <plugin filename="libLiftDragPlugin.so" name="aerodynamics_1_leftFront_plugin">
      <link_name>propeller_1_leftFront_link</link_name>
      <!-- Name of the link affected by the group of lift/drag properties -->
      <air_density>1.225</air_density>
      <!-- Density of the fluid this model is suspended in -->
      <area>1.0</area>
      <!-- Surface area of the link -->
      <a0>0.1</a0>
      <!-- The initial "alpha" or initial angle of attack -->
      <cla>0.1</cla>
      <!-- The ratio of the coefficient of lift and alpha slope before stall -->
      <cda>0.01</cda>
      <!-- The ratio of the coefficient of drag and alpha slope before stall -->
      <cma>0.0</cma>
      <!-- The ratio of the coefficient of momentum and alpha slope before stall -->
      <cp>0 -0.11375 0</cp>
      <!-- Center of pressure -->
      <forward>-1 0 0</forward>
      <!-- 3-vector representing the forward direction of motion in the link frame (-Y AXIS) -->
      <upward>0 0 1</upward>
      <!-- 3-vector representing the direction of lift or drag (Z AXIS) -->
      <alpha_stall>0.2</alpha_stall>
      <!-- Angle of attack at stall point; the peak angle of attack -->
      <cla_stall>-0.2</cla_stall>
      <!-- The ratio of coefficient of lift and alpha slope after stall -->
      <cda_stall>1.0</cda_stall>
      <!-- The ratio of coefficient of drag and alpha slope after stall -->
      <cma_stall>0.0</cma_stall>
    </plugin>
  </gazebo>
  <!-- Propeller 2 -->
  <gazebo>
    <plugin filename="libLiftDragPlugin.so" name="aerodynamics_2_leftFront_plugin">
      <link_name>propeller_2_leftFront_link</link_name>
      <!-- Name of the link affected by the group of lift/drag properties -->
      <air_density>1.225</air_density>
      <!-- Density of the fluid this model is suspended in -->
      <area>1.0</area>
      <!-- Surface area of the link -->
      <a0>0.1</a0>
      <!-- The initial "alpha" or initial angle of attack -->
      <cla>0.1</cla>
      <!-- The ratio of the coefficient of lift and alpha slope before stall -->
      <cda>0.01</cda>
      <!-- The ratio of the coefficient of drag and alpha slope before stall -->
      <cma>0.0</cma>
      <!-- The ratio of the coefficient of momentum and alpha slope before stall -->
      <cp>0 0.11375 0</cp>
      <!-- Center of pressure. The forces due to lift and drag will be applied here (GC) -->
      <forward>1 0 0</forward>
      <!-- 3-vector representing the forward direction of motion in the link frame (+Y AXIS) -->
      <upward>0 0 1</upward>
      <!-- 3-vector representing the direction of lift or drag (Z AXIS) -->
      <alpha_stall>0.2</alpha_stall>
      <!-- Angle of attack at stall point; the peak angle of attack -->
      <cla_stall>-0.2</cla_stall>
      <!-- The ratio of coefficient of lift and alpha slope after stall -->
      <cda_stall>1.0</cda_stall>
      <!-- The ratio of coefficient of drag and alpha slope after stall -->
      <cma_stall>0.0</cma_stall>
    </plugin>
  </gazebo>
  <!-- 2 Propellers per rotor -->
  <!-- Propeller 1 -->
  <gazebo>
    <plugin filename="libLiftDragPlugin.so" name="aerodynamics_1_rightRear_plugin">
      <link_name>propeller_1_rightRear_link</link_name>
      <!-- Name of the link affected by the group of lift/drag properties -->
      <air_density>1.225</air_density>
      <!-- Density of the fluid this model is suspended in -->
      <area>1.0</area>
      <!-- Surface area of the link -->
      <a0>0.1</a0>
      <!-- The initial "alpha" or initial angle of attack -->
      <cla>0.1</cla>
      <!-- The ratio of the coefficient of lift and alpha slope before stall -->
      <cda>0.01</cda>
      <!-- The ratio of the coefficient of drag and alpha slope before stall -->
      <cma>0.0</cma>
      <!-- The ratio of the coefficient of momentum and alpha slope before stall -->
      <cp>0 -0.11375 0</cp>
      <!-- Center of pressure -->
      <forward>-1 0 0</forward>
      <!-- 3-vector representing the forward direction of motion in the link frame (-Y AXIS) -->
      <upward>0 0 1</upward>
      <!-- 3-vector representing the direction of lift or drag (Z AXIS) -->
      <alpha_stall>0.2</alpha_stall>
      <!-- Angle of attack at stall point; the peak angle of attack -->
      <cla_stall>-0.2</cla_stall>
      <!-- The ratio of coefficient of lift and alpha slope after stall -->
      <cda_stall>1.0</cda_stall>
      <!-- The ratio of coefficient of drag and alpha slope after stall -->
      <cma_stall>0.0</cma_stall>
    </plugin>
  </gazebo>
  <!-- Propeller 2 -->
  <gazebo>
    <plugin filename="libLiftDragPlugin.so" name="aerodynamics_2_rightRear_plugin">
      <link_name>propeller_2_rightRear_link</link_name>
      <!-- Name of the link affected by the group of lift/drag properties -->
      <air_density>1.225</air_density>
      <!-- Density of the fluid this model is suspended in -->
      <area>1.0</area>
      <!-- Surface area of the link -->
      <a0>0.1</a0>
      <!-- The initial "alpha" or initial angle of attack -->
      <cla>0.1</cla>
      <!-- The ratio of the coefficient of lift and alpha slope before stall -->
      <cda>0.01</cda>
      <!-- The ratio of the coefficient of drag and alpha slope before stall -->
      <cma>0.0</cma>
      <!-- The ratio of the coefficient of momentum and alpha slope before stall -->
      <cp>0 0.11375 0</cp>
      <!-- Center of pressure. The forces due to lift and drag will be applied here (GC) -->
      <forward>1 0 0</forward>
      <!-- 3-vector representing the forward direction of motion in the link frame (+Y AXIS) -->
      <upward>0 0 1</upward>
      <!-- 3-vector representing the direction of lift or drag (Z AXIS) -->
      <alpha_stall>0.2</alpha_stall>
      <!-- Angle of attack at stall point; the peak angle of attack -->
      <cla_stall>-0.2</cla_stall>
      <!-- The ratio of coefficient of lift and alpha slope after stall -->
      <cda_stall>1.0</cda_stall>
      <!-- The ratio of coefficient of drag and alpha slope after stall -->
      <cma_stall>0.0</cma_stall>
    </plugin>
  </gazebo>
  <!-- 2 Propellers per rotor -->
  <!-- Propeller 1 -->
  <gazebo>
    <plugin filename="libLiftDragPlugin.so" name="aerodynamics_1_leftRear_plugin">
      <link_name>propeller_1_leftRear_link</link_name>
      <!-- Name of the link affected by the group of lift/drag properties -->
      <air_density>1.225</air_density>
      <!-- Density of the fluid this model is suspended in -->
      <area>1.0</area>
      <!-- Surface area of the link -->
      <a0>0.1</a0>
      <!-- The initial "alpha" or initial angle of attack -->
      <cla>0.1</cla>
      <!-- The ratio of the coefficient of lift and alpha slope before stall -->
      <cda>0.01</cda>
      <!-- The ratio of the coefficient of drag and alpha slope before stall -->
      <cma>0.0</cma>
      <!-- The ratio of the coefficient of momentum and alpha slope before stall -->
      <cp>0 -0.11375 0</cp>
      <!-- Center of pressure -->
      <forward>1 0 0</forward>
      <!-- 3-vector representing the forward direction of motion in the link frame (-Y AXIS) -->
      <upward>0 0 1</upward>
      <!-- 3-vector representing the direction of lift or drag (Z AXIS) -->
      <alpha_stall>0.2</alpha_stall>
      <!-- Angle of attack at stall point; the peak angle of attack -->
      <cla_stall>-0.2</cla_stall>
      <!-- The ratio of coefficient of lift and alpha slope after stall -->
      <cda_stall>1.0</cda_stall>
      <!-- The ratio of coefficient of drag and alpha slope after stall -->
      <cma_stall>0.0</cma_stall>
    </plugin>
  </gazebo>
  <!-- Propeller 2 -->
  <gazebo>
    <plugin filename="libLiftDragPlugin.so" name="aerodynamics_2_leftRear_plugin">
      <link_name>propeller_2_leftRear_link</link_name>
      <!-- Name of the link affected by the group of lift/drag properties -->
      <air_density>1.225</air_density>
      <!-- Density of the fluid this model is suspended in -->
      <area>1.0</area>
      <!-- Surface area of the link -->
      <a0>0.1</a0>
      <!-- The initial "alpha" or initial angle of attack -->
      <cla>0.1</cla>
      <!-- The ratio of the coefficient of lift and alpha slope before stall -->
      <cda>0.01</cda>
      <!-- The ratio of the coefficient of drag and alpha slope before stall -->
      <cma>0.0</cma>
      <!-- The ratio of the coefficient of momentum and alpha slope before stall -->
      <cp>0 0.11375 0</cp>
      <!-- Center of pressure. The forces due to lift and drag will be applied here (GC) -->
      <forward>-1 0 0</forward>
      <!-- 3-vector representing the forward direction of motion in the link frame (+Y AXIS) -->
      <upward>0 0 1</upward>
      <!-- 3-vector representing the direction of lift or drag (Z AXIS) -->
      <alpha_stall>0.2</alpha_stall>
      <!-- Angle of attack at stall point; the peak angle of attack -->
      <cla_stall>-0.2</cla_stall>
      <!-- The ratio of coefficient of lift and alpha slope after stall -->
      <cda_stall>1.0</cda_stall>
      <!-- The ratio of coefficient of drag and alpha slope after stall -->
      <cma_stall>0.0</cma_stall>
    </plugin>
  </gazebo>
  <!-- Camera sensors -->
  <link name="frontRightCamera">
    <inertial>
      <origin rpy="0 0 0" xyz="0 0 0"/>
      <mass value="0.000001"/>
      <inertia ixx="0.000001" ixy="0.0" ixz="0.0" iyy="0.000001" iyz="0.0" izz="0.000001"/>
    </inertial>
  </link>
  <joint name="FrontRightCamera2GroundCore" type="fixed">
    <parent link="frame_link"/>
    <child link="frontRightCamera"/>
    <axis xyz="0 0 0"/>
    <origin rpy="0 0.0 3.141592" xyz="-0.25 0.05 0.1"/>
  </joint>
  <gazebo reference="frontRightCamera">
    <sensor name="frontRightCamera" type="camera">
      <update_rate>0.4</update_rate>
      <camera name="frontRightCamera">
        <horizontal_fov>1.570796</horizontal_fov>
        <image>
          <width>1280</width>
          <height>720</height>
          <format>R8G8B8</format>
        </image>
        <clip>
          <near>0.01</near>
          <far>100.0</far>
        </clip>
        <noise>
          <type>gaussian</type>
          <mean>0.0</mean>
          <stddev>0.0</stddev>
        </noise>
      </camera>
      <plugin filename="libgazebo_ros_camera.so" name="camera_plugin">
        <alwaysOn>true</alwaysOn>
        <updateRate>0.4</updateRate>
        <cameraName>sensors/frontRightCamera</cameraName>
        <imageTopicName>image</imageTopicName>
        <cameraInfoTopicName>info</cameraInfoTopicName>
        <frameName>frontRightCamera</frameName>
      </plugin>
    </sensor>
  </gazebo>
  <link name="frontLeftCamera">
    <inertial>
      <origin rpy="0 0 0" xyz="0 0 0"/>
      <mass value="0.000001"/>
      <inertia ixx="0.000001" ixy="0.0" ixz="0.0" iyy="0.000001" iyz="0.0" izz="0.000001"/>
    </inertial>
  </link>
  <joint name="FrontLeftCamera2GroundCore" type="fixed">
    <parent link="frame_link"/>
    <child link="frontLeftCamera"/>
    <axis xyz="0 0 0"/>
    <origin rpy="0 0.0 3.141592" xyz="-0.25 -0.05 0.1"/>
  </joint>
  <gazebo reference="frontLeftCamera">
    <sensor name="frontLeftCamera" type="camera">
      <update_rate>0.4</update_rate>
      <camera name="frontLeftCamera">
        <horizontal_fov>1.570796</horizontal_fov>
        <image>
          <width>1280</width>
          <height>720</height>
          <format>R8G8B8</format>
        </image>
        <clip>
          <near>0.01</near>
          <far>100.0</far>
        </clip>
        <noise>
          <type>gaussian</type>
          <mean>0.0</mean>
          <stddev>0.0</stddev>
        </noise>
      </camera>
      <plugin filename="libgazebo_ros_camera.so" name="camera_plugin">
        <alwaysOn>true</alwaysOn>
        <updateRate>0.4</updateRate>
        <cameraName>sensors/frontLeftCamera</cameraName>
        <imageTopicName>image</imageTopicName>
        <cameraInfoTopicName>info</cameraInfoTopicName>
        <frameName>frontLeftCamera</frameName>
      </plugin>
    </sensor>
  </gazebo>
  <!-- END -->
  <!-- Ultrasonic sensors -->
  <link name="frontUltrasonic">
    <inertial>
      <origin rpy="0 0 0" xyz="0 0 0"/>
      <mass value="0.000001"/>
      <inertia ixx="0.000001" ixy="0.0" ixz="0.0" iyy="0.000001" iyz="0.0" izz="0.000001"/>
    </inertial>
  </link>
  <joint name="FrontUltrasonic2GroundCore" type="fixed">
    <parent link="frame_link"/>
    <child link="frontUltrasonic"/>
    <axis xyz="0 0 0"/>
    <origin rpy="0 0 3.141592" xyz="-0.13 0.0 0"/>
  </joint>
  <gazebo reference="frontUltrasonic">
    <sensor name="frontUltrasonic" type="ray">
      <update_rate>1</update_rate>
      <visualize>true</visualize>
      <ray>
        <scan>
          <horizontal>
            <samples>10</samples>
            <resolution>1</resolution>
            <min_angle>-0.05</min_angle>
            <max_angle>0.05</max_angle>
          </horizontal>
        </scan>
        <range>
          <min>0.02</min>
          <max>6</max>
          <resolution>0.03</resolution>
        </range>
      </ray>
      <plugin filename="libgazebo_ros_range.so" name="ultrasonic_plugin">
        <gaussianNoise>0.0</gaussianNoise>
        <alwaysOn>true</alwaysOn>
        <updateRate>1</updateRate>
        <topicName>sensors/frontUltrasonic</topicName>
        <frameName>frontUltrasonic</frameName>
        <radiation>ultrasound</radiation>
        <fov>0.05--0.05</fov>
        <visualize>true</visualize>
      </plugin>
    </sensor>
  </gazebo>
  <link name="leftUltrasonic">
    <inertial>
      <origin rpy="0 0 0" xyz="0 0 0"/>
      <mass value="0.000001"/>
      <inertia ixx="0.000001" ixy="0.0" ixz="0.0" iyy="0.000001" iyz="0.0" izz="0.000001"/>
    </inertial>
  </link>
  <joint name="LeftUltrasonic2GroundCore" type="fixed">
    <parent link="frame_link"/>
    <child link="leftUltrasonic"/>
    <axis xyz="0 0 0"/>
    <origin rpy="0 0 2.6179933333333336" xyz="-0.13 -0.075 0"/>
  </joint>
  <gazebo reference="leftUltrasonic">
    <sensor name="leftUltrasonic" type="ray">
      <update_rate>1</update_rate>
      <visualize>true</visualize>
      <ray>
        <scan>
          <horizontal>
            <samples>10</samples>
            <resolution>1</resolution>
            <min_angle>-0.05</min_angle>
            <max_angle>0.05</max_angle>
          </horizontal>
        </scan>
        <range>
          <min>0.02</min>
          <max>6</max>
          <resolution>0.03</resolution>
        </range>
      </ray>
      <plugin filename="libgazebo_ros_range.so" name="ultrasonic_plugin">
        <gaussianNoise>0.0</gaussianNoise>
        <alwaysOn>true</alwaysOn>
        <updateRate>1</updateRate>
        <topicName>sensors/leftUltrasonic</topicName>
        <frameName>leftUltrasonic</frameName>
        <radiation>ultrasound</radiation>
        <fov>0.05--0.05</fov>
        <visualize>true</visualize>
      </plugin>
    </sensor>
  </gazebo>
  <link name="rightUltrasonic">
    <inertial>
      <origin rpy="0 0 0" xyz="0 0 0"/>
      <mass value="0.000001"/>
      <inertia ixx="0.000001" ixy="0.0" ixz="0.0" iyy="0.000001" iyz="0.0" izz="0.000001"/>
    </inertial>
  </link>
  <joint name="RightUltrasonic2GroundCore" type="fixed">
    <parent link="frame_link"/>
    <child link="rightUltrasonic"/>
    <axis xyz="0 0 0"/>
    <origin rpy="0 0 3.6651906666666667" xyz="-0.13 0.075 0"/>
  </joint>
  <gazebo reference="rightUltrasonic">
    <sensor name="rightUltrasonic" type="ray">
      <update_rate>1</update_rate>
      <visualize>true</visualize>
      <ray>
        <scan>
          <horizontal>
            <samples>10</samples>
            <resolution>1</resolution>
            <min_angle>-0.05</min_angle>
            <max_angle>0.05</max_angle>
          </horizontal>
        </scan>
        <range>
          <min>0.02</min>
          <max>6</max>
          <resolution>0.03</resolution>
        </range>
      </ray>
      <plugin filename="libgazebo_ros_range.so" name="ultrasonic_plugin">
        <gaussianNoise>0.0</gaussianNoise>
        <alwaysOn>true</alwaysOn>
        <updateRate>1</updateRate>
        <topicName>sensors/rightUltrasonic</topicName>
        <frameName>rightUltrasonic</frameName>
        <radiation>ultrasound</radiation>
        <fov>0.05--0.05</fov>
        <visualize>true</visualize>
      </plugin>
    </sensor>
  </gazebo>
  <!-- END -->
  <link name="visualCamera">
    <inertial>
      <origin rpy="0 0 0" xyz="0 0 0"/>
      <mass value="0.000001"/>
      <inertia ixx="0.000001" ixy="0.0" ixz="0.0" iyy="0.000001" iyz="0.0" izz="0.000001"/>
    </inertial>
  </link>
  <joint name="visualCamera_joint" type="fixed">
    <parent link="frame_link"/>
    <child link="visualCamera"/>
    <axis xyz="0 0 0"/>
    <origin rpy="0 0.2 3.15" xyz="1.2 0.0 0.5"/>
  </joint>
  <gazebo reference="visualCamera">
    <sensor name="visualCamera" type="camera">
      <update_rate>15</update_rate>
      <camera name="visualCamera">
        <horizontal_fov>1.75</horizontal_fov>
        <image>
          <width>1280</width>
          <height>720</height>
          <format>R8G8B8</format>
        </image>
        <clip>
          <near>0.001</near>
          <far>100.0</far>
        </clip>
        <noise>
          <type>gaussian</type>
          <mean>0.0</mean>
          <stddev>0.0</stddev>
        </noise>
      </camera>
      <plugin filename="libgazebo_ros_camera.so" name="camera_plugin">
        <alwaysOn>true</alwaysOn>
        <updateRate>15</updateRate>
        <cameraName>sensors/visualCamera</cameraName>
        <imageTopicName>image</imageTopicName>
        <cameraInfoTopicName>info</cameraInfoTopicName>
        <frameName>visualCamera</frameName>
      </plugin>
    </sensor>
  </gazebo>
  <!-- 2. ROBOT DEFINITION -->
  <!-- Robot = base + frame + 4 wheels + 4 motors -->
  <link name="base_link"/>
  <!-- 2.1 Frame -->
  <!-- Frame = link + joint -->
  <link name="frame_link">
    <inertial>
      <origin rpy="0 0 0" xyz="0 0 0"/>
      <mass value="0.5"/>
      <inertia ixx="0.0005208333333333333" ixy="0.0" ixz="0.0" iyy="0.0013666666666666664" iyz="0.0" izz="0.0018541666666666665"/>
    </inertial>
    <visual>
      <origin rpy="0 0 0" xyz="0.004 0 -0.02"/>
      <geometry>
        <mesh filename="package://simulator/model/meshes/frame.dae" scale="1 1 1"/>
      </geometry>
    </visual>
    <collision>
      <origin rpy="0 0 0" xyz="0 0 0"/>
      <geometry>
        <box size="0.18 0.11 0.02"/>
      </geometry>
    </collision>
  </link>
  <joint name="frame_joint" type="fixed">
    <parent link="base_link"/>
    <child link="frame_link"/>
    <axis xyz="0 0 0"/>
    <origin rpy="0 0 0" xyz="0 0 0"/>
  </joint>
  <!-- 2.2 Wheels -->
  <!-- Wheel = axle + tire -->
  <!-- 3.1 Axle = link + joint -->
  <link name="axle_rightFront_link">
    <inertial>
      <origin rpy="0 0 0" xyz="0 0 0"/>
      <mass value="0.0016666666666666668"/>
      <inertia ixx="4.1473765432098767e-07" ixy="0.0" ixz="0.0" iyy="4.1473765432098767e-07" iyz="0.0" izz="5.208333333333335e-07"/>
    </inertial>
    <collision>
      <origin rpy="0 0 0" xyz="0 0 0"/>
      <geometry>
        <cylinder length="0.03333333333333333" radius="0.025"/>
      </geometry>
    </collision>
  </link>
  <joint name="axle_rightFront_joint" type="fixed">
    <parent link="frame_link"/>
    <child link="axle_rightFront_link"/>
    <axis xyz="0 0 0"/>
    <origin rpy="1.570796 0 0" xyz="0.07 -0.05 -0.05"/>
  </joint>
  <!-- 3.2 Tire = link + joint -->
  <link name="tire_rightFront_link">
    <inertial>
      <origin rpy="0 0 0" xyz="0 0 0"/>
      <mass value="0.0033333333333333335"/>
      <inertia ixx="2.160493827160494e-06" ixy="0.0" ixz="0.0" iyy="2.160493827160494e-06" iyz="0.0" izz="4.166666666666668e-06"/>
    </inertial>
    <collision>
      <origin rpy="0 0 0" xyz="0 0 0"/>
      <geometry>
        <cylinder length="0.016666666666666666" radius="0.05"/>
      </geometry>
    </collision>
  </link>
  <joint name="tire_rightFront_joint" type="continuous">
    <parent link="axle_rightFront_link"/>
    <child link="tire_rightFront_link"/>
    <axis xyz="0 0 1"/>
    <origin rpy="0 0 0" xyz="0 0 0.03333333333333333"/>
    <dynamics damping="0.1" friction="0.1"/>
    <limit effort="50" velocity="50"/>
  </joint>
  <!-- Wheel = axle + tire -->
  <!-- 3.1 Axle = link + joint -->
  <link name="axle_leftFront_link">
    <inertial>
      <origin rpy="0 0 0" xyz="0 0 0"/>
      <mass value="0.0016666666666666668"/>
      <inertia ixx="4.1473765432098767e-07" ixy="0.0" ixz="0.0" iyy="4.1473765432098767e-07" iyz="0.0" izz="5.208333333333335e-07"/>
    </inertial>
    <collision>
      <origin rpy="0 0 0" xyz="0 0 0"/>
      <geometry>
        <cylinder length="0.03333333333333333" radius="0.025"/>
      </geometry>
    </collision>
  </link>
  <joint name="axle_leftFront_joint" type="fixed">
    <parent link="frame_link"/>
    <child link="axle_leftFront_link"/>
    <axis xyz="0 0 0"/>
    <origin rpy="1.570796 0 0" xyz="0.07 0.05 -0.05"/>
  </joint>
  <!-- 3.2 Tire = link + joint -->
  <link name="tire_leftFront_link">
    <inertial>
      <origin rpy="0 0 0" xyz="0 0 0"/>
      <mass value="0.0033333333333333335"/>
      <inertia ixx="2.160493827160494e-06" ixy="0.0" ixz="0.0" iyy="2.160493827160494e-06" iyz="0.0" izz="4.166666666666668e-06"/>
    </inertial>
    <collision>
      <origin rpy="0 0 0" xyz="0 0 0"/>
      <geometry>
        <cylinder length="0.016666666666666666" radius="0.05"/>
      </geometry>
    </collision>
  </link>
  <joint name="tire_leftFront_joint" type="continuous">
    <parent link="axle_leftFront_link"/>
    <child link="tire_leftFront_link"/>
    <axis xyz="0 0 1"/>
    <origin rpy="0 0 0" xyz="0 0 -0.03333333333333333"/>
    <dynamics damping="0.1" friction="0.1"/>
    <limit effort="50" velocity="50"/>
  </joint>
  <!-- Wheel = axle + tire -->
  <!-- 3.1 Axle = link + joint -->
  <link name="axle_rightRear_link">
    <inertial>
      <origin rpy="0 0 0" xyz="0 0 0"/>
      <mass value="0.0016666666666666668"/>
      <inertia ixx="4.1473765432098767e-07" ixy="0.0" ixz="0.0" iyy="4.1473765432098767e-07" iyz="0.0" izz="5.208333333333335e-07"/>
    </inertial>
    <collision>
      <origin rpy="0 0 0" xyz="0 0 0"/>
      <geometry>
        <cylinder length="0.03333333333333333" radius="0.025"/>
      </geometry>
    </collision>
  </link>
  <joint name="axle_rightRear_joint" type="fixed">
    <parent link="frame_link"/>
    <child link="axle_rightRear_link"/>
    <axis xyz="0 0 0"/>
    <origin rpy="1.570796 0 0" xyz="-0.07 -0.05 -0.05"/>
  </joint>
  <!-- 3.2 Tire = link + joint -->
  <link name="tire_rightRear_link">
    <inertial>
      <origin rpy="0 0 0" xyz="0 0 0"/>
      <mass value="0.0033333333333333335"/>
      <inertia ixx="2.160493827160494e-06" ixy="0.0" ixz="0.0" iyy="2.160493827160494e-06" iyz="0.0" izz="4.166666666666668e-06"/>
    </inertial>
    <collision>
      <origin rpy="0 0 0" xyz="0 0 0"/>
      <geometry>
        <cylinder length="0.016666666666666666" radius="0.05"/>
      </geometry>
    </collision>
  </link>
  <joint name="tire_rightRear_joint" type="continuous">
    <parent link="axle_rightRear_link"/>
    <child link="tire_rightRear_link"/>
    <axis xyz="0 0 1"/>
    <origin rpy="0 0 0" xyz="0 0 0.03333333333333333"/>
    <dynamics damping="0.1" friction="0.1"/>
    <limit effort="50" velocity="50"/>
  </joint>
  <!-- Wheel = axle + tire -->
  <!-- 3.1 Axle = link + joint -->
  <link name="axle_leftRear_link">
    <inertial>
      <origin rpy="0 0 0" xyz="0 0 0"/>
      <mass value="0.0016666666666666668"/>
      <inertia ixx="4.1473765432098767e-07" ixy="0.0" ixz="0.0" iyy="4.1473765432098767e-07" iyz="0.0" izz="5.208333333333335e-07"/>
    </inertial>
    <collision>
      <origin rpy="0 0 0" xyz="0 0 0"/>
      <geometry>
        <cylinder length="0.03333333333333333" radius="0.025"/>
      </geometry>
    </collision>
  </link>
  <joint name="axle_leftRear_joint" type="fixed">
    <parent link="frame_link"/>
    <child link="axle_leftRear_link"/>
    <axis xyz="0 0 0"/>
    <origin rpy="1.570796 0 0" xyz="-0.07 0.05 -0.05"/>
  </joint>
  <!-- 3.2 Tire = link + joint -->
  <link name="tire_leftRear_link">
    <inertial>
      <origin rpy="0 0 0" xyz="0 0 0"/>
      <mass value="0.0033333333333333335"/>
      <inertia ixx="2.160493827160494e-06" ixy="0.0" ixz="0.0" iyy="2.160493827160494e-06" iyz="0.0" izz="4.166666666666668e-06"/>
    </inertial>
    <collision>
      <origin rpy="0 0 0" xyz="0 0 0"/>
      <geometry>
        <cylinder length="0.016666666666666666" radius="0.05"/>
      </geometry>
    </collision>
  </link>
  <joint name="tire_leftRear_joint" type="continuous">
    <parent link="axle_leftRear_link"/>
    <child link="tire_leftRear_link"/>
    <axis xyz="0 0 1"/>
    <origin rpy="0 0 0" xyz="0 0 -0.03333333333333333"/>
    <dynamics damping="0.1" friction="0.1"/>
    <limit effort="50" velocity="50"/>
  </joint>
  <!-- 2.3 Motors -->
  <!-- Motor = stator + rotor + 2 propellers -->
  <!-- 4.1 Stator = link + joint -->
  <link name="stator_rightFront_link">
    <inertial>
      <origin rpy="0 0 0" xyz="0 0 0"/>
      <mass value="0.001"/>
      <inertia ixx="1.2314814814814815e-07" ixy="0.0" ixz="0.0" iyy="1.2314814814814815e-07" iyz="0.0" izz="2.0000000000000002e-07"/>
    </inertial>
    <collision>
      <origin rpy="0 0 0" xyz="0 0 0"/>
      <geometry>
        <cylinder length="0.016666666666666666" radius="0.02"/>
      </geometry>
    </collision>
  </link>
  <joint name="stator_rightFront_joint" type="fixed">
    <parent link="frame_link"/>
    <child link="stator_rightFront_link"/>
    <axis xyz="0 0 0"/>
    <origin rpy="0 0 0" xyz="0.2 -0.2 0"/>
  </joint>
  <!-- 4.2 Rotor = link + joint + transmission -->
  <link name="rotor_rightFront_link">
    <inertial>
      <origin rpy="0 0 0" xyz="0 0 0"/>
      <mass value="0.002"/>
      <inertia ixx="3.851851851851852e-07" ixy="0.0" ixz="0.0" iyy="3.851851851851852e-07" iyz="0.0" izz="4.0000000000000003e-07"/>
    </inertial>
    <collision>
      <origin rpy="0 0 0" xyz="0 0 0"/>
      <geometry>
        <cylinder length="0.03333333333333333" radius="0.02"/>
      </geometry>
    </collision>
  </link>
  <joint name="rotor_rightFront_joint" type="continuous">
    <parent link="stator_rightFront_link"/>
    <child link="rotor_rightFront_link"/>
    <axis xyz="0 0 1"/>
    <origin rpy="0 0 0" xyz="0 0 0.03333333333333333"/>
  </joint>
  <transmission name="rotor_rightFront_transmission">
    <type>transmission_interface/SimpleTransmission</type>
    <joint name="rotor_rightFront_joint">
      <hardwareInterface>hardware_interface/VelocityJointInterface</hardwareInterface>
    </joint>
    <actuator name="rotor_rightFront_actuator">
      <mechanicalReduction>1</mechanicalReduction>
      <hardwareInterface>hardware_interface/VelocityJointInterface</hardwareInterface>
    </actuator>
  </transmission>
  <!-- 4.3 Propeller 1 = link + joint -->
  <link name="propeller_1_rightFront_link">
    <inertial>
      <origin rpy="1.570796 0 0" xyz="0 0 0"/>
      <mass value="0.001"/>
      <inertia ixx="1.8807870370370369e-06" ixy="0.0" ixz="0.0" iyy="2.0083333333333333e-06" iyz="0.0" izz="1.3912037037037038e-07"/>
    </inertial>
    <collision>
      <origin rpy="1.570796 0 0" xyz="0 0 0"/>
      <geometry>
        <box size="0.04 0.008333333333333333 0.15"/>
      </geometry>
    </collision>
  </link>
  <joint name="propeller_1_rightFront_joint" type="fixed">
    <parent link="rotor_rightFront_link"/>
    <child link="propeller_1_rightFront_link"/>
    <axis xyz="0 0 0"/>
    <origin rpy="0 0 0" xyz="0 -0.11375 0"/>
  </joint>
  <gazebo reference="propeller_1_rightFront_joint">
    <preserveFixedJoint>true</preserveFixedJoint>
  </gazebo>
  <!-- 4.4 Propeller 2 = link + joint -->
  <link name="propeller_2_rightFront_link">
    <inertial>
      <origin rpy="1.570796 0 0" xyz="0 0 0"/>
      <mass value="0.001"/>
      <inertia ixx="1.8807870370370369e-06" ixy="0.0" ixz="0.0" iyy="2.0083333333333333e-06" iyz="0.0" izz="1.3912037037037038e-07"/>
    </inertial>
    <collision>
      <origin rpy="1.570796 0 0" xyz="0 0 0"/>
      <geometry>
        <box size="0.04 0.008333333333333333 0.15"/>
      </geometry>
    </collision>
  </link>
  <joint name="propeller_2_rightFront_joint" type="fixed">
    <parent link="rotor_rightFront_link"/>
    <child link="propeller_2_rightFront_link"/>
    <axis xyz="0 0 0"/>
    <origin rpy="0 0 0" xyz="0 0.11375 0"/>
  </joint>
  <gazebo reference="propeller_2_rightFront_joint">
    <preserveFixedJoint>true</preserveFixedJoint>
  </gazebo>
  <!-- Motor = stator + rotor + 2 propellers -->
  <!-- 4.1 Stator = link + joint -->
  <link name="stator_leftFront_link">
    <inertial>
      <origin rpy="0 0 0" xyz="0 0 0"/>
      <mass value="0.001"/>
      <inertia ixx="1.2314814814814815e-07" ixy="0.0" ixz="0.0" iyy="1.2314814814814815e-07" iyz="0.0" izz="2.0000000000000002e-07"/>
    </inertial>
    <collision>
      <origin rpy="0 0 0" xyz="0 0 0"/>
      <geometry>
        <cylinder length="0.016666666666666666" radius="0.02"/>
      </geometry>
    </collision>
  </link>
  <joint name="stator_leftFront_joint" type="fixed">
    <parent link="frame_link"/>
    <child link="stator_leftFront_link"/>
    <axis xyz="0 0 0"/>
    <origin rpy="0 0 0" xyz="0.2 0.2 0"/>
  </joint>
  <!-- 4.2 Rotor = link + joint + transmission -->
  <link name="rotor_leftFront_link">
    <inertial>
      <origin rpy="0 0 0" xyz="0 0 0"/>
      <mass value="0.002"/>
      <inertia ixx="3.851851851851852e-07" ixy="0.0" ixz="0.0" iyy="3.851851851851852e-07" iyz="0.0" izz="4.0000000000000003e-07"/>
    </inertial>
    <collision>
      <origin rpy="0 0 0" xyz="0 0 0"/>
      <geometry>
        <cylinder length="0.03333333333333333" radius="0.02"/>
      </geometry>
    </collision>
  </link>
  <joint name="rotor_leftFront_joint" type="continuous">
    <parent link="stator_leftFront_link"/>
    <child link="rotor_leftFront_link"/>
    <axis xyz="0 0 1"/>
    <origin rpy="0 0 0" xyz="0 0 0.03333333333333333"/>
  </joint>
  <transmission name="rotor_leftFront_transmission">
    <type>transmission_interface/SimpleTransmission</type>
    <joint name="rotor_leftFront_joint">
      <hardwareInterface>hardware_interface/VelocityJointInterface</hardwareInterface>
    </joint>
    <actuator name="rotor_leftFront_actuator">
      <mechanicalReduction>1</mechanicalReduction>
      <hardwareInterface>hardware_interface/VelocityJointInterface</hardwareInterface>
    </actuator>
  </transmission>
  <!-- 4.3 Propeller 1 = link + joint -->
  <link name="propeller_1_leftFront_link">
    <inertial>
      <origin rpy="1.570796 0 0" xyz="0 0 0"/>
      <mass value="0.001"/>
      <inertia ixx="1.8807870370370369e-06" ixy="0.0" ixz="0.0" iyy="2.0083333333333333e-06" iyz="0.0" izz="1.3912037037037038e-07"/>
    </inertial>
    <collision>
      <origin rpy="1.570796 0 0" xyz="0 0 0"/>
      <geometry>
        <box size="0.04 0.008333333333333333 0.15"/>
      </geometry>
    </collision>
  </link>
  <joint name="propeller_1_leftFront_joint" type="fixed">
    <parent link="rotor_leftFront_link"/>
    <child link="propeller_1_leftFront_link"/>
    <axis xyz="0 0 0"/>
    <origin rpy="0 0 0" xyz="0 -0.11375 0"/>
  </joint>
  <gazebo reference="propeller_1_leftFront_joint">
    <preserveFixedJoint>true</preserveFixedJoint>
  </gazebo>
  <!-- 4.4 Propeller 2 = link + joint -->
  <link name="propeller_2_leftFront_link">
    <inertial>
      <origin rpy="1.570796 0 0" xyz="0 0 0"/>
      <mass value="0.001"/>
      <inertia ixx="1.8807870370370369e-06" ixy="0.0" ixz="0.0" iyy="2.0083333333333333e-06" iyz="0.0" izz="1.3912037037037038e-07"/>
    </inertial>
    <collision>
      <origin rpy="1.570796 0 0" xyz="0 0 0"/>
      <geometry>
        <box size="0.04 0.008333333333333333 0.15"/>
      </geometry>
    </collision>
  </link>
  <joint name="propeller_2_leftFront_joint" type="fixed">
    <parent link="rotor_leftFront_link"/>
    <child link="propeller_2_leftFront_link"/>
    <axis xyz="0 0 0"/>
    <origin rpy="0 0 0" xyz="0 0.11375 0"/>
  </joint>
  <gazebo reference="propeller_2_leftFront_joint">
    <preserveFixedJoint>true</preserveFixedJoint>
  </gazebo>
  <!-- Motor = stator + rotor + 2 propellers -->
  <!-- 4.1 Stator = link + joint -->
  <link name="stator_rightRear_link">
    <inertial>
      <origin rpy="0 0 0" xyz="0 0 0"/>
      <mass value="0.001"/>
      <inertia ixx="1.2314814814814815e-07" ixy="0.0" ixz="0.0" iyy="1.2314814814814815e-07" iyz="0.0" izz="2.0000000000000002e-07"/>
    </inertial>
    <collision>
      <origin rpy="0 0 0" xyz="0 0 0"/>
      <geometry>
        <cylinder length="0.016666666666666666" radius="0.02"/>
      </geometry>
    </collision>
  </link>
  <joint name="stator_rightRear_joint" type="fixed">
    <parent link="frame_link"/>
    <child link="stator_rightRear_link"/>
    <axis xyz="0 0 0"/>
    <origin rpy="0 0 0" xyz="-0.2 -0.2 0"/>
  </joint>
  <!-- 4.2 Rotor = link + joint + transmission -->
  <link name="rotor_rightRear_link">
    <inertial>
      <origin rpy="0 0 0" xyz="0 0 0"/>
      <mass value="0.002"/>
      <inertia ixx="3.851851851851852e-07" ixy="0.0" ixz="0.0" iyy="3.851851851851852e-07" iyz="0.0" izz="4.0000000000000003e-07"/>
    </inertial>
    <collision>
      <origin rpy="0 0 0" xyz="0 0 0"/>
      <geometry>
        <cylinder length="0.03333333333333333" radius="0.02"/>
      </geometry>
    </collision>
  </link>
  <joint name="rotor_rightRear_joint" type="continuous">
    <parent link="stator_rightRear_link"/>
    <child link="rotor_rightRear_link"/>
    <axis xyz="0 0 1"/>
    <origin rpy="0 0 0" xyz="0 0 0.03333333333333333"/>
  </joint>
  <transmission name="rotor_rightRear_transmission">
    <type>transmission_interface/SimpleTransmission</type>
    <joint name="rotor_rightRear_joint">
      <hardwareInterface>hardware_interface/VelocityJointInterface</hardwareInterface>
    </joint>
    <actuator name="rotor_rightRear_actuator">
      <mechanicalReduction>1</mechanicalReduction>
      <hardwareInterface>hardware_interface/VelocityJointInterface</hardwareInterface>
    </actuator>
  </transmission>
  <!-- 4.3 Propeller 1 = link + joint -->
  <link name="propeller_1_rightRear_link">
    <inertial>
      <origin rpy="1.570796 0 0" xyz="0 0 0"/>
      <mass value="0.001"/>
      <inertia ixx="1.8807870370370369e-06" ixy="0.0" ixz="0.0" iyy="2.0083333333333333e-06" iyz="0.0" izz="1.3912037037037038e-07"/>
    </inertial>
    <collision>
      <origin rpy="1.570796 0 0" xyz="0 0 0"/>
      <geometry>
        <box size="0.04 0.008333333333333333 0.15"/>
      </geometry>
    </collision>
  </link>
  <joint name="propeller_1_rightRear_joint" type="fixed">
    <parent link="rotor_rightRear_link"/>
    <child link="propeller_1_rightRear_link"/>
    <axis xyz="0 0 0"/>
    <origin rpy="0 0 0" xyz="0 -0.11375 0"/>
  </joint>
  <gazebo reference="propeller_1_rightRear_joint">
    <preserveFixedJoint>true</preserveFixedJoint>
  </gazebo>
  <!-- 4.4 Propeller 2 = link + joint -->
  <link name="propeller_2_rightRear_link">
    <inertial>
      <origin rpy="1.570796 0 0" xyz="0 0 0"/>
      <mass value="0.001"/>
      <inertia ixx="1.8807870370370369e-06" ixy="0.0" ixz="0.0" iyy="2.0083333333333333e-06" iyz="0.0" izz="1.3912037037037038e-07"/>
    </inertial>
    <collision>
      <origin rpy="1.570796 0 0" xyz="0 0 0"/>
      <geometry>
        <box size="0.04 0.008333333333333333 0.15"/>
      </geometry>
    </collision>
  </link>
  <joint name="propeller_2_rightRear_joint" type="fixed">
    <parent link="rotor_rightRear_link"/>
    <child link="propeller_2_rightRear_link"/>
    <axis xyz="0 0 0"/>
    <origin rpy="0 0 0" xyz="0 0.11375 0"/>
  </joint>
  <gazebo reference="propeller_2_rightRear_joint">
    <preserveFixedJoint>true</preserveFixedJoint>
  </gazebo>
  <!-- Motor = stator + rotor + 2 propellers -->
  <!-- 4.1 Stator = link + joint -->
  <link name="stator_leftRear_link">
    <inertial>
      <origin rpy="0 0 0" xyz="0 0 0"/>
      <mass value="0.001"/>
      <inertia ixx="1.2314814814814815e-07" ixy="0.0" ixz="0.0" iyy="1.2314814814814815e-07" iyz="0.0" izz="2.0000000000000002e-07"/>
    </inertial>
    <collision>
      <origin rpy="0 0 0" xyz="0 0 0"/>
      <geometry>
        <cylinder length="0.016666666666666666" radius="0.02"/>
      </geometry>
    </collision>
  </link>
  <joint name="stator_leftRear_joint" type="fixed">
    <parent link="frame_link"/>
    <child link="stator_leftRear_link"/>
    <axis xyz="0 0 0"/>
    <origin rpy="0 0 0" xyz="-0.2 0.2 0"/>
  </joint>
  <!-- 4.2 Rotor = link + joint + transmission -->
  <link name="rotor_leftRear_link">
    <inertial>
      <origin rpy="0 0 0" xyz="0 0 0"/>
      <mass value="0.002"/>
      <inertia ixx="3.851851851851852e-07" ixy="0.0" ixz="0.0" iyy="3.851851851851852e-07" iyz="0.0" izz="4.0000000000000003e-07"/>
    </inertial>
    <collision>
      <origin rpy="0 0 0" xyz="0 0 0"/>
      <geometry>
        <cylinder length="0.03333333333333333" radius="0.02"/>
      </geometry>
    </collision>
  </link>
  <joint name="rotor_leftRear_joint" type="continuous">
    <parent link="stator_leftRear_link"/>
    <child link="rotor_leftRear_link"/>
    <axis xyz="0 0 1"/>
    <origin rpy="0 0 0" xyz="0 0 0.03333333333333333"/>
  </joint>
  <transmission name="rotor_leftRear_transmission">
    <type>transmission_interface/SimpleTransmission</type>
    <joint name="rotor_leftRear_joint">
      <hardwareInterface>hardware_interface/VelocityJointInterface</hardwareInterface>
    </joint>
    <actuator name="rotor_leftRear_actuator">
      <mechanicalReduction>1</mechanicalReduction>
      <hardwareInterface>hardware_interface/VelocityJointInterface</hardwareInterface>
    </actuator>
  </transmission>
  <!-- 4.3 Propeller 1 = link + joint -->
  <link name="propeller_1_leftRear_link">
    <inertial>
      <origin rpy="1.570796 0 0" xyz="0 0 0"/>
      <mass value="0.001"/>
      <inertia ixx="1.8807870370370369e-06" ixy="0.0" ixz="0.0" iyy="2.0083333333333333e-06" iyz="0.0" izz="1.3912037037037038e-07"/>
    </inertial>
    <collision>
      <origin rpy="1.570796 0 0" xyz="0 0 0"/>
      <geometry>
        <box size="0.04 0.008333333333333333 0.15"/>
      </geometry>
    </collision>
  </link>
  <joint name="propeller_1_leftRear_joint" type="fixed">
    <parent link="rotor_leftRear_link"/>
    <child link="propeller_1_leftRear_link"/>
    <axis xyz="0 0 0"/>
    <origin rpy="0 0 0" xyz="0 -0.11375 0"/>
  </joint>
  <gazebo reference="propeller_1_leftRear_joint">
    <preserveFixedJoint>true</preserveFixedJoint>
  </gazebo>
  <!-- 4.4 Propeller 2 = link + joint -->
  <link name="propeller_2_leftRear_link">
    <inertial>
      <origin rpy="1.570796 0 0" xyz="0 0 0"/>
      <mass value="0.001"/>
      <inertia ixx="1.8807870370370369e-06" ixy="0.0" ixz="0.0" iyy="2.0083333333333333e-06" iyz="0.0" izz="1.3912037037037038e-07"/>
    </inertial>
    <collision>
      <origin rpy="1.570796 0 0" xyz="0 0 0"/>
      <geometry>
        <box size="0.04 0.008333333333333333 0.15"/>
      </geometry>
    </collision>
  </link>
  <joint name="propeller_2_leftRear_joint" type="fixed">
    <parent link="rotor_leftRear_link"/>
    <child link="propeller_2_leftRear_link"/>
    <axis xyz="0 0 0"/>
    <origin rpy="0 0 0" xyz="0 0.11375 0"/>
  </joint>
  <gazebo reference="propeller_2_leftRear_joint">
    <preserveFixedJoint>true</preserveFixedJoint>
  </gazebo>
</robot>
<!-- ############################################################################ 
     ###################### Self-Driving Simulator - ARAV ####################### 
     ############################################################################
     #################### Author : Alberto Ceballos Gonzalez #################### 
     ######## E-mail : alberto.ceballos-gonzalez@student.isae-supaero.fr ######## 
     ######### (c) Copyright 2021. Alberto Ceballos. All Rights Reserved ########  
     ############################################################################ -->

