<sdf version='1.7'>
  <model name='arav'>
    <link name='base_link'>
      <inertial>
        <pose>1e-06 -0 -0.000651 0 -0 0</pose>
        <mass>0.510673</mass>
        <inertia>
          <ixx>0.000722388</ixx>
          <ixy>1.63791e-24</ixy>
          <ixz>-5.50202e-07</ixz>
          <iyy>0.00158624</iyy>
          <iyz>-1.38686e-13</iyz>
          <izz>0.00223359</izz>
        </inertia>
      </inertial>
      <collision name='base_link_fixed_joint_lump__frame_link_collision'>
        <pose>0 0 0 0 -0 0</pose>
        <geometry>
          <box>
            <size>0.18 0.11 0.02</size>
          </box>
        </geometry>
      </collision>
      <collision name='base_link_fixed_joint_lump__axle_leftFront_link_collision_1'>
        <pose>0.07 0.05 -0.05 1.5708 -0 0</pose>
        <geometry>
          <cylinder>
            <length>0.0333333</length>
            <radius>0.025</radius>
          </cylinder>
        </geometry>
      </collision>
      <collision name='base_link_fixed_joint_lump__axle_leftRear_link_collision_2'>
        <pose>-0.07 0.05 -0.05 1.5708 -0 0</pose>
        <geometry>
          <cylinder>
            <length>0.0333333</length>
            <radius>0.025</radius>
          </cylinder>
        </geometry>
      </collision>
      <collision name='base_link_fixed_joint_lump__axle_rightFront_link_collision_3'>
        <pose>0.07 -0.05 -0.05 1.5708 -0 0</pose>
        <geometry>
          <cylinder>
            <length>0.0333333</length>
            <radius>0.025</radius>
          </cylinder>
        </geometry>
      </collision>
      <collision name='base_link_fixed_joint_lump__axle_rightRear_link_collision_4'>
        <pose>-0.07 -0.05 -0.05 1.5708 -0 0</pose>
        <geometry>
          <cylinder>
            <length>0.0333333</length>
            <radius>0.025</radius>
          </cylinder>
        </geometry>
      </collision>
      <collision name='base_link_fixed_joint_lump__stator_leftFront_link_collision_5'>
        <pose>0.2 0.2 0 0 -0 0</pose>
        <geometry>
          <cylinder>
            <length>0.0166667</length>
            <radius>0.02</radius>
          </cylinder>
        </geometry>
      </collision>
      <collision name='base_link_fixed_joint_lump__stator_leftRear_link_collision_6'>
        <pose>-0.2 0.2 0 0 -0 0</pose>
        <geometry>
          <cylinder>
            <length>0.0166667</length>
            <radius>0.02</radius>
          </cylinder>
        </geometry>
      </collision>
      <collision name='base_link_fixed_joint_lump__stator_rightFront_link_collision_7'>
        <pose>0.2 -0.2 0 0 -0 0</pose>
        <geometry>
          <cylinder>
            <length>0.0166667</length>
            <radius>0.02</radius>
          </cylinder>
        </geometry>
      </collision>
      <collision name='base_link_fixed_joint_lump__stator_rightRear_link_collision_8'>
        <pose>-0.2 -0.2 0 0 -0 0</pose>
        <geometry>
          <cylinder>
            <length>0.0166667</length>
            <radius>0.02</radius>
          </cylinder>
        </geometry>
      </collision>
      <visual name='base_link_fixed_joint_lump__frame_link_visual'>
        <pose>0.004 0 -0.02 0 -0 0</pose>
        <geometry>
          <mesh>
            <scale>1 1 1</scale>
            <uri>model://arav/meshes/frame.dae</uri>
          </mesh>
        </geometry>
      </visual>
      <sensor name='frontLeftCamera' type='camera'>
        <update_rate>0.4</update_rate>
        <camera name='frontLeftCamera'>
          <horizontal_fov>1.5708</horizontal_fov>
          <image>
            <width>1280</width>
            <height>720</height>
            <format>R8G8B8</format>
          </image>
          <clip>
            <near>0.01</near>
            <far>100</far>
          </clip>
          <noise>
            <type>gaussian</type>
            <mean>0</mean>
            <stddev>0</stddev>
          </noise>
        </camera>
        <plugin name='camera_plugin' filename='libgazebo_ros_camera.so'>
          <alwaysOn>1</alwaysOn>
          <updateRate>0.4</updateRate>
          <cameraName>sensors/frontLeftCamera</cameraName>
          <imageTopicName>image</imageTopicName>
          <cameraInfoTopicName>info</cameraInfoTopicName>
          <frameName>frontLeftCamera</frameName>
        </plugin>
        <pose>-0.25 -0.05 0.1 0 -0 3.14159</pose>
      </sensor>
      <sensor name='frontRightCamera' type='camera'>
        <update_rate>0.4</update_rate>
        <camera name='frontRightCamera'>
          <horizontal_fov>1.5708</horizontal_fov>
          <image>
            <width>1280</width>
            <height>720</height>
            <format>R8G8B8</format>
          </image>
          <clip>
            <near>0.01</near>
            <far>100</far>
          </clip>
          <noise>
            <type>gaussian</type>
            <mean>0</mean>
            <stddev>0</stddev>
          </noise>
        </camera>
        <plugin name='camera_plugin' filename='libgazebo_ros_camera.so'>
          <alwaysOn>1</alwaysOn>
          <updateRate>0.4</updateRate>
          <cameraName>sensors/frontRightCamera</cameraName>
          <imageTopicName>image</imageTopicName>
          <cameraInfoTopicName>info</cameraInfoTopicName>
          <frameName>frontRightCamera</frameName>
        </plugin>
        <pose>-0.25 0.05 0.1 0 -0 3.14159</pose>
      </sensor>
      <sensor name='frontUltrasonic' type='ray'>
        <update_rate>1</update_rate>
        <visualize>1</visualize>
        <ray>
          <scan>
            <horizontal>
              <samples>10</samples>
              <resolution>1</resolution>
              <min_angle>-0.05</min_angle>
              <max_angle>0.05</max_angle>
            </horizontal>
          </scan>
          <range>
            <min>0.02</min>
            <max>6</max>
            <resolution>0.03</resolution>
          </range>
        </ray>
        <plugin name='ultrasonic_plugin' filename='libgazebo_ros_range.so'>
          <gaussianNoise>0.0</gaussianNoise>
          <alwaysOn>1</alwaysOn>
          <updateRate>1</updateRate>
          <topicName>sensors/frontUltrasonic</topicName>
          <frameName>frontUltrasonic</frameName>
          <radiation>ultrasound</radiation>
          <fov>0.05--0.05</fov>
          <visualize>1</visualize>
        </plugin>
        <pose>-0.13 0 0 0 -0 3.14159</pose>
      </sensor>
      <sensor name='leftUltrasonic' type='ray'>
        <update_rate>1</update_rate>
        <visualize>1</visualize>
        <ray>
          <scan>
            <horizontal>
              <samples>10</samples>
              <resolution>1</resolution>
              <min_angle>-0.05</min_angle>
              <max_angle>0.05</max_angle>
            </horizontal>
          </scan>
          <range>
            <min>0.02</min>
            <max>6</max>
            <resolution>0.03</resolution>
          </range>
        </ray>
        <plugin name='ultrasonic_plugin' filename='libgazebo_ros_range.so'>
          <gaussianNoise>0.0</gaussianNoise>
          <alwaysOn>1</alwaysOn>
          <updateRate>1</updateRate>
          <topicName>sensors/leftUltrasonic</topicName>
          <frameName>leftUltrasonic</frameName>
          <radiation>ultrasound</radiation>
          <fov>0.05--0.05</fov>
          <visualize>1</visualize>
        </plugin>
        <pose>-0.13 -0.075 0 0 -0 2.61799</pose>
      </sensor>
      <sensor name='rightUltrasonic' type='ray'>
        <update_rate>1</update_rate>
        <visualize>1</visualize>
        <ray>
          <scan>
            <horizontal>
              <samples>10</samples>
              <resolution>1</resolution>
              <min_angle>-0.05</min_angle>
              <max_angle>0.05</max_angle>
            </horizontal>
          </scan>
          <range>
            <min>0.02</min>
            <max>6</max>
            <resolution>0.03</resolution>
          </range>
        </ray>
        <plugin name='ultrasonic_plugin' filename='libgazebo_ros_range.so'>
          <gaussianNoise>0.0</gaussianNoise>
          <alwaysOn>1</alwaysOn>
          <updateRate>1</updateRate>
          <topicName>sensors/rightUltrasonic</topicName>
          <frameName>rightUltrasonic</frameName>
          <radiation>ultrasound</radiation>
          <fov>0.05--0.05</fov>
          <visualize>1</visualize>
        </plugin>
        <pose>-0.13 0.075 0 0 0 -2.61799</pose>
      </sensor>
      <sensor name='visualCamera' type='camera'>
        <update_rate>15</update_rate>
        <camera name='visualCamera'>
          <horizontal_fov>1.75</horizontal_fov>
          <image>
            <width>1280</width>
            <height>720</height>
            <format>R8G8B8</format>
          </image>
          <clip>
            <near>0.001</near>
            <far>100</far>
          </clip>
          <noise>
            <type>gaussian</type>
            <mean>0</mean>
            <stddev>0</stddev>
          </noise>
        </camera>
        <plugin name='camera_plugin' filename='libgazebo_ros_camera.so'>
          <alwaysOn>1</alwaysOn>
          <updateRate>15</updateRate>
          <cameraName>sensors/visualCamera</cameraName>
          <imageTopicName>image</imageTopicName>
          <cameraInfoTopicName>info</cameraInfoTopicName>
          <frameName>visualCamera</frameName>
        </plugin>
        <pose>1.2 0 0.5 0 0.2 -3.13319</pose>
      </sensor>
    </link>
    <joint name='tire_leftFront_joint' type='revolute'>
      <pose relative_to='base_link'>0.07 0.083333 -0.05 1.5708 -0 0</pose>
      <parent>base_link</parent>
      <child>tire_leftFront_link</child>
      <axis>
        <xyz>0 0 1</xyz>
        <limit>
          <effort>50</effort>
          <velocity>50</velocity>
          <lower>-1e+16</lower>
          <upper>1e+16</upper>
        </limit>
        <dynamics>
          <damping>0.1</damping>
          <friction>0.1</friction>
          <spring_reference>0</spring_reference>
          <spring_stiffness>0</spring_stiffness>
        </dynamics>
      </axis>
    </joint>
    <link name='tire_leftFront_link'>
      <pose relative_to='tire_leftFront_joint'>0 0 0 0 -0 0</pose>
      <inertial>
        <pose>0 0 0 0 -0 0</pose>
        <mass>0.00333333</mass>
        <inertia>
          <ixx>2.16049e-06</ixx>
          <ixy>0</ixy>
          <ixz>0</ixz>
          <iyy>2.16049e-06</iyy>
          <iyz>0</iyz>
          <izz>4.16667e-06</izz>
        </inertia>
      </inertial>
      <collision name='tire_leftFront_link_collision'>
        <pose>0 0 0 0 -0 0</pose>
        <geometry>
          <cylinder>
            <length>0.0166667</length>
            <radius>0.05</radius>
          </cylinder>
        </geometry>
      </collision>
    </link>
    <joint name='tire_leftRear_joint' type='revolute'>
      <pose relative_to='base_link'>-0.07 0.083333 -0.05 1.5708 -0 0</pose>
      <parent>base_link</parent>
      <child>tire_leftRear_link</child>
      <axis>
        <xyz>0 0 1</xyz>
        <limit>
          <effort>50</effort>
          <velocity>50</velocity>
          <lower>-1e+16</lower>
          <upper>1e+16</upper>
        </limit>
        <dynamics>
          <damping>0.1</damping>
          <friction>0.1</friction>
          <spring_reference>0</spring_reference>
          <spring_stiffness>0</spring_stiffness>
        </dynamics>
      </axis>
    </joint>
    <link name='tire_leftRear_link'>
      <pose relative_to='tire_leftRear_joint'>0 0 0 0 -0 0</pose>
      <inertial>
        <pose>0 0 0 0 -0 0</pose>
        <mass>0.00333333</mass>
        <inertia>
          <ixx>2.16049e-06</ixx>
          <ixy>0</ixy>
          <ixz>0</ixz>
          <iyy>2.16049e-06</iyy>
          <iyz>0</iyz>
          <izz>4.16667e-06</izz>
        </inertia>
      </inertial>
      <collision name='tire_leftRear_link_collision'>
        <pose>0 0 0 0 -0 0</pose>
        <geometry>
          <cylinder>
            <length>0.0166667</length>
            <radius>0.05</radius>
          </cylinder>
        </geometry>
      </collision>
    </link>
    <joint name='tire_rightFront_joint' type='revolute'>
      <pose relative_to='base_link'>0.07 -0.083333 -0.05 1.5708 -0 0</pose>
      <parent>base_link</parent>
      <child>tire_rightFront_link</child>
      <axis>
        <xyz>0 0 1</xyz>
        <limit>
          <effort>50</effort>
          <velocity>50</velocity>
          <lower>-1e+16</lower>
          <upper>1e+16</upper>
        </limit>
        <dynamics>
          <damping>0.1</damping>
          <friction>0.1</friction>
          <spring_reference>0</spring_reference>
          <spring_stiffness>0</spring_stiffness>
        </dynamics>
      </axis>
    </joint>
    <link name='tire_rightFront_link'>
      <pose relative_to='tire_rightFront_joint'>0 0 0 0 -0 0</pose>
      <inertial>
        <pose>0 0 0 0 -0 0</pose>
        <mass>0.00333333</mass>
        <inertia>
          <ixx>2.16049e-06</ixx>
          <ixy>0</ixy>
          <ixz>0</ixz>
          <iyy>2.16049e-06</iyy>
          <iyz>0</iyz>
          <izz>4.16667e-06</izz>
        </inertia>
      </inertial>
      <collision name='tire_rightFront_link_collision'>
        <pose>0 0 0 0 -0 0</pose>
        <geometry>
          <cylinder>
            <length>0.0166667</length>
            <radius>0.05</radius>
          </cylinder>
        </geometry>
      </collision>
    </link>
    <joint name='tire_rightRear_joint' type='revolute'>
      <pose relative_to='base_link'>-0.07 -0.083333 -0.05 1.5708 -0 0</pose>
      <parent>base_link</parent>
      <child>tire_rightRear_link</child>
      <axis>
        <xyz>0 0 1</xyz>
        <limit>
          <effort>50</effort>
          <velocity>50</velocity>
          <lower>-1e+16</lower>
          <upper>1e+16</upper>
        </limit>
        <dynamics>
          <damping>0.1</damping>
          <friction>0.1</friction>
          <spring_reference>0</spring_reference>
          <spring_stiffness>0</spring_stiffness>
        </dynamics>
      </axis>
    </joint>
    <link name='tire_rightRear_link'>
      <pose relative_to='tire_rightRear_joint'>0 0 0 0 -0 0</pose>
      <inertial>
        <pose>0 0 0 0 -0 0</pose>
        <mass>0.00333333</mass>
        <inertia>
          <ixx>2.16049e-06</ixx>
          <ixy>0</ixy>
          <ixz>0</ixz>
          <iyy>2.16049e-06</iyy>
          <iyz>0</iyz>
          <izz>4.16667e-06</izz>
        </inertia>
      </inertial>
      <collision name='tire_rightRear_link_collision'>
        <pose>0 0 0 0 -0 0</pose>
        <geometry>
          <cylinder>
            <length>0.0166667</length>
            <radius>0.05</radius>
          </cylinder>
        </geometry>
      </collision>
    </link>
    <joint name='rotor_leftFront_joint' type='revolute'>
      <pose relative_to='base_link'>0.2 0.2 0.033333 0 -0 0</pose>
      <parent>base_link</parent>
      <child>rotor_leftFront_link</child>
      <axis>
        <xyz>0 0 1</xyz>
        <limit>
          <lower>-1e+16</lower>
          <upper>1e+16</upper>
        </limit>
        <dynamics>
          <spring_reference>0</spring_reference>
          <spring_stiffness>0</spring_stiffness>
        </dynamics>
      </axis>
    </joint>
    <link name='rotor_leftFront_link'>
      <pose relative_to='rotor_leftFront_joint'>0 0 0 0 -0 0</pose>
      <inertial>
        <pose>0 0 0 0 -0 0</pose>
        <mass>0.002</mass>
        <inertia>
          <ixx>3.85185e-07</ixx>
          <ixy>0</ixy>
          <ixz>0</ixz>
          <iyy>3.85185e-07</iyy>
          <iyz>0</iyz>
          <izz>4e-07</izz>
        </inertia>
      </inertial>
      <collision name='rotor_leftFront_link_collision'>
        <pose>0 0 0 0 -0 0</pose>
        <geometry>
          <cylinder>
            <length>0.0333333</length>
            <radius>0.02</radius>
          </cylinder>
        </geometry>
      </collision>
    </link>
    <joint name='propeller_1_leftFront_joint' type='fixed'>
      <pose relative_to='rotor_leftFront_link'>0 -0.11375 0 0 -0 0</pose>
      <parent>rotor_leftFront_link</parent>
      <child>propeller_1_leftFront_link</child>
      <axis>
        <dynamics>
          <spring_reference>0</spring_reference>
          <spring_stiffness>0</spring_stiffness>
        </dynamics>
        <xyz>0 0 1</xyz>
        <limit>
          <lower>-1e+16</lower>
          <upper>1e+16</upper>
        </limit>
      </axis>
      <physics>
        <ode>
          <limit>
            <cfm>0</cfm>
            <erp>0.2</erp>
          </limit>
        </ode>
      </physics>
    </joint>
    <link name='propeller_1_leftFront_link'>
      <pose relative_to='propeller_1_leftFront_joint'>0 0 0 0 -0 0</pose>
      <inertial>
        <pose>0 0 0 1.5708 -0 0</pose>
        <mass>0.001</mass>
        <inertia>
          <ixx>1.88079e-06</ixx>
          <ixy>0</ixy>
          <ixz>0</ixz>
          <iyy>2.00833e-06</iyy>
          <iyz>0</iyz>
          <izz>1.3912e-07</izz>
        </inertia>
      </inertial>
      <collision name='propeller_1_leftFront_link_collision'>
        <pose>0 0 0 1.5708 -0 0</pose>
        <geometry>
          <box>
            <size>0.04 0.008333 0.15</size>
          </box>
        </geometry>
      </collision>
    </link>
    <joint name='propeller_2_leftFront_joint' type='fixed'>
      <pose relative_to='rotor_leftFront_link'>0 0.11375 0 0 -0 0</pose>
      <parent>rotor_leftFront_link</parent>
      <child>propeller_2_leftFront_link</child>
      <axis>
        <dynamics>
          <spring_reference>0</spring_reference>
          <spring_stiffness>0</spring_stiffness>
        </dynamics>
        <xyz>0 0 1</xyz>
        <limit>
          <lower>-1e+16</lower>
          <upper>1e+16</upper>
        </limit>
      </axis>
      <physics>
        <ode>
          <limit>
            <cfm>0</cfm>
            <erp>0.2</erp>
          </limit>
        </ode>
      </physics>
    </joint>
    <link name='propeller_2_leftFront_link'>
      <pose relative_to='propeller_2_leftFront_joint'>0 0 0 0 -0 0</pose>
      <inertial>
        <pose>0 0 0 1.5708 -0 0</pose>
        <mass>0.001</mass>
        <inertia>
          <ixx>1.88079e-06</ixx>
          <ixy>0</ixy>
          <ixz>0</ixz>
          <iyy>2.00833e-06</iyy>
          <iyz>0</iyz>
          <izz>1.3912e-07</izz>
        </inertia>
      </inertial>
      <collision name='propeller_2_leftFront_link_collision'>
        <pose>0 0 0 1.5708 -0 0</pose>
        <geometry>
          <box>
            <size>0.04 0.008333 0.15</size>
          </box>
        </geometry>
      </collision>
    </link>
    <joint name='rotor_leftRear_joint' type='revolute'>
      <pose relative_to='base_link'>-0.2 0.2 0.033333 0 -0 0</pose>
      <parent>base_link</parent>
      <child>rotor_leftRear_link</child>
      <axis>
        <xyz>0 0 1</xyz>
        <limit>
          <lower>-1e+16</lower>
          <upper>1e+16</upper>
        </limit>
        <dynamics>
          <spring_reference>0</spring_reference>
          <spring_stiffness>0</spring_stiffness>
        </dynamics>
      </axis>
    </joint>
    <link name='rotor_leftRear_link'>
      <pose relative_to='rotor_leftRear_joint'>0 0 0 0 -0 0</pose>
      <inertial>
        <pose>0 0 0 0 -0 0</pose>
        <mass>0.002</mass>
        <inertia>
          <ixx>3.85185e-07</ixx>
          <ixy>0</ixy>
          <ixz>0</ixz>
          <iyy>3.85185e-07</iyy>
          <iyz>0</iyz>
          <izz>4e-07</izz>
        </inertia>
      </inertial>
      <collision name='rotor_leftRear_link_collision'>
        <pose>0 0 0 0 -0 0</pose>
        <geometry>
          <cylinder>
            <length>0.0333333</length>
            <radius>0.02</radius>
          </cylinder>
        </geometry>
      </collision>
    </link>
    <joint name='propeller_1_leftRear_joint' type='fixed'>
      <pose relative_to='rotor_leftRear_link'>0 -0.11375 0 0 -0 0</pose>
      <parent>rotor_leftRear_link</parent>
      <child>propeller_1_leftRear_link</child>
      <axis>
        <dynamics>
          <spring_reference>0</spring_reference>
          <spring_stiffness>0</spring_stiffness>
        </dynamics>
        <xyz>0 0 1</xyz>
        <limit>
          <lower>-1e+16</lower>
          <upper>1e+16</upper>
        </limit>
      </axis>
      <physics>
        <ode>
          <limit>
            <cfm>0</cfm>
            <erp>0.2</erp>
          </limit>
        </ode>
      </physics>
    </joint>
    <link name='propeller_1_leftRear_link'>
      <pose relative_to='propeller_1_leftRear_joint'>0 0 0 0 -0 0</pose>
      <inertial>
        <pose>0 0 0 1.5708 -0 0</pose>
        <mass>0.001</mass>
        <inertia>
          <ixx>1.88079e-06</ixx>
          <ixy>0</ixy>
          <ixz>0</ixz>
          <iyy>2.00833e-06</iyy>
          <iyz>0</iyz>
          <izz>1.3912e-07</izz>
        </inertia>
      </inertial>
      <collision name='propeller_1_leftRear_link_collision'>
        <pose>0 0 0 1.5708 -0 0</pose>
        <geometry>
          <box>
            <size>0.04 0.008333 0.15</size>
          </box>
        </geometry>
      </collision>
    </link>
    <joint name='propeller_2_leftRear_joint' type='fixed'>
      <pose relative_to='rotor_leftRear_link'>0 0.11375 0 0 -0 0</pose>
      <parent>rotor_leftRear_link</parent>
      <child>propeller_2_leftRear_link</child>
      <axis>
        <dynamics>
          <spring_reference>0</spring_reference>
          <spring_stiffness>0</spring_stiffness>
        </dynamics>
        <xyz>0 0 1</xyz>
        <limit>
          <lower>-1e+16</lower>
          <upper>1e+16</upper>
        </limit>
      </axis>
      <physics>
        <ode>
          <limit>
            <cfm>0</cfm>
            <erp>0.2</erp>
          </limit>
        </ode>
      </physics>
    </joint>
    <link name='propeller_2_leftRear_link'>
      <pose relative_to='propeller_2_leftRear_joint'>0 0 0 0 -0 0</pose>
      <inertial>
        <pose>0 0 0 1.5708 -0 0</pose>
        <mass>0.001</mass>
        <inertia>
          <ixx>1.88079e-06</ixx>
          <ixy>0</ixy>
          <ixz>0</ixz>
          <iyy>2.00833e-06</iyy>
          <iyz>0</iyz>
          <izz>1.3912e-07</izz>
        </inertia>
      </inertial>
      <collision name='propeller_2_leftRear_link_collision'>
        <pose>0 0 0 1.5708 -0 0</pose>
        <geometry>
          <box>
            <size>0.04 0.008333 0.15</size>
          </box>
        </geometry>
      </collision>
    </link>
    <joint name='rotor_rightFront_joint' type='revolute'>
      <pose relative_to='base_link'>0.2 -0.2 0.033333 0 -0 0</pose>
      <parent>base_link</parent>
      <child>rotor_rightFront_link</child>
      <axis>
        <xyz>0 0 1</xyz>
        <limit>
          <lower>-1e+16</lower>
          <upper>1e+16</upper>
        </limit>
        <dynamics>
          <spring_reference>0</spring_reference>
          <spring_stiffness>0</spring_stiffness>
        </dynamics>
      </axis>
    </joint>
    <link name='rotor_rightFront_link'>
      <pose relative_to='rotor_rightFront_joint'>0 0 0 0 -0 0</pose>
      <inertial>
        <pose>0 0 0 0 -0 0</pose>
        <mass>0.002</mass>
        <inertia>
          <ixx>3.85185e-07</ixx>
          <ixy>0</ixy>
          <ixz>0</ixz>
          <iyy>3.85185e-07</iyy>
          <iyz>0</iyz>
          <izz>4e-07</izz>
        </inertia>
      </inertial>
      <collision name='rotor_rightFront_link_collision'>
        <pose>0 0 0 0 -0 0</pose>
        <geometry>
          <cylinder>
            <length>0.0333333</length>
            <radius>0.02</radius>
          </cylinder>
        </geometry>
      </collision>
    </link>
    <joint name='propeller_1_rightFront_joint' type='fixed'>
      <pose relative_to='rotor_rightFront_link'>0 -0.11375 0 0 -0 0</pose>
      <parent>rotor_rightFront_link</parent>
      <child>propeller_1_rightFront_link</child>
      <axis>
        <dynamics>
          <spring_reference>0</spring_reference>
          <spring_stiffness>0</spring_stiffness>
        </dynamics>
        <xyz>0 0 1</xyz>
        <limit>
          <lower>-1e+16</lower>
          <upper>1e+16</upper>
        </limit>
      </axis>
      <physics>
        <ode>
          <limit>
            <cfm>0</cfm>
            <erp>0.2</erp>
          </limit>
        </ode>
      </physics>
    </joint>
    <link name='propeller_1_rightFront_link'>
      <pose relative_to='propeller_1_rightFront_joint'>0 0 0 0 -0 0</pose>
      <inertial>
        <pose>0 0 0 1.5708 -0 0</pose>
        <mass>0.001</mass>
        <inertia>
          <ixx>1.88079e-06</ixx>
          <ixy>0</ixy>
          <ixz>0</ixz>
          <iyy>2.00833e-06</iyy>
          <iyz>0</iyz>
          <izz>1.3912e-07</izz>
        </inertia>
      </inertial>
      <collision name='propeller_1_rightFront_link_collision'>
        <pose>0 0 0 1.5708 -0 0</pose>
        <geometry>
          <box>
            <size>0.04 0.008333 0.15</size>
          </box>
        </geometry>
      </collision>
    </link>
    <joint name='propeller_2_rightFront_joint' type='fixed'>
      <pose relative_to='rotor_rightFront_link'>0 0.11375 0 0 -0 0</pose>
      <parent>rotor_rightFront_link</parent>
      <child>propeller_2_rightFront_link</child>
      <axis>
        <dynamics>
          <spring_reference>0</spring_reference>
          <spring_stiffness>0</spring_stiffness>
        </dynamics>
        <xyz>0 0 1</xyz>
        <limit>
          <lower>-1e+16</lower>
          <upper>1e+16</upper>
        </limit>
      </axis>
      <physics>
        <ode>
          <limit>
            <cfm>0</cfm>
            <erp>0.2</erp>
          </limit>
        </ode>
      </physics>
    </joint>
    <link name='propeller_2_rightFront_link'>
      <pose relative_to='propeller_2_rightFront_joint'>0 0 0 0 -0 0</pose>
      <inertial>
        <pose>0 0 0 1.5708 -0 0</pose>
        <mass>0.001</mass>
        <inertia>
          <ixx>1.88079e-06</ixx>
          <ixy>0</ixy>
          <ixz>0</ixz>
          <iyy>2.00833e-06</iyy>
          <iyz>0</iyz>
          <izz>1.3912e-07</izz>
        </inertia>
      </inertial>
      <collision name='propeller_2_rightFront_link_collision'>
        <pose>0 0 0 1.5708 -0 0</pose>
        <geometry>
          <box>
            <size>0.04 0.008333 0.15</size>
          </box>
        </geometry>
      </collision>
    </link>
    <joint name='rotor_rightRear_joint' type='revolute'>
      <pose relative_to='base_link'>-0.2 -0.2 0.033333 0 -0 0</pose>
      <parent>base_link</parent>
      <child>rotor_rightRear_link</child>
      <axis>
        <xyz>0 0 1</xyz>
        <limit>
          <lower>-1e+16</lower>
          <upper>1e+16</upper>
        </limit>
        <dynamics>
          <spring_reference>0</spring_reference>
          <spring_stiffness>0</spring_stiffness>
        </dynamics>
      </axis>
    </joint>
    <link name='rotor_rightRear_link'>
      <pose relative_to='rotor_rightRear_joint'>0 0 0 0 -0 0</pose>
      <inertial>
        <pose>0 0 0 0 -0 0</pose>
        <mass>0.002</mass>
        <inertia>
          <ixx>3.85185e-07</ixx>
          <ixy>0</ixy>
          <ixz>0</ixz>
          <iyy>3.85185e-07</iyy>
          <iyz>0</iyz>
          <izz>4e-07</izz>
        </inertia>
      </inertial>
      <collision name='rotor_rightRear_link_collision'>
        <pose>0 0 0 0 -0 0</pose>
        <geometry>
          <cylinder>
            <length>0.0333333</length>
            <radius>0.02</radius>
          </cylinder>
        </geometry>
      </collision>
    </link>
    <joint name='propeller_1_rightRear_joint' type='fixed'>
      <pose relative_to='rotor_rightRear_link'>0 -0.11375 0 0 -0 0</pose>
      <parent>rotor_rightRear_link</parent>
      <child>propeller_1_rightRear_link</child>
      <axis>
        <dynamics>
          <spring_reference>0</spring_reference>
          <spring_stiffness>0</spring_stiffness>
        </dynamics>
        <xyz>0 0 1</xyz>
        <limit>
          <lower>-1e+16</lower>
          <upper>1e+16</upper>
        </limit>
      </axis>
      <physics>
        <ode>
          <limit>
            <cfm>0</cfm>
            <erp>0.2</erp>
          </limit>
        </ode>
      </physics>
    </joint>
    <link name='propeller_1_rightRear_link'>
      <pose relative_to='propeller_1_rightRear_joint'>0 0 0 0 -0 0</pose>
      <inertial>
        <pose>0 0 0 1.5708 -0 0</pose>
        <mass>0.001</mass>
        <inertia>
          <ixx>1.88079e-06</ixx>
          <ixy>0</ixy>
          <ixz>0</ixz>
          <iyy>2.00833e-06</iyy>
          <iyz>0</iyz>
          <izz>1.3912e-07</izz>
        </inertia>
      </inertial>
      <collision name='propeller_1_rightRear_link_collision'>
        <pose>0 0 0 1.5708 -0 0</pose>
        <geometry>
          <box>
            <size>0.04 0.008333 0.15</size>
          </box>
        </geometry>
      </collision>
    </link>
    <joint name='propeller_2_rightRear_joint' type='fixed'>
      <pose relative_to='rotor_rightRear_link'>0 0.11375 0 0 -0 0</pose>
      <parent>rotor_rightRear_link</parent>
      <child>propeller_2_rightRear_link</child>
      <axis>
        <dynamics>
          <spring_reference>0</spring_reference>
          <spring_stiffness>0</spring_stiffness>
        </dynamics>
        <xyz>0 0 1</xyz>
        <limit>
          <lower>-1e+16</lower>
          <upper>1e+16</upper>
        </limit>
      </axis>
      <physics>
        <ode>
          <limit>
            <cfm>0</cfm>
            <erp>0.2</erp>
          </limit>
        </ode>
      </physics>
    </joint>
    <link name='propeller_2_rightRear_link'>
      <pose relative_to='propeller_2_rightRear_joint'>0 0 0 0 -0 0</pose>
      <inertial>
        <pose>0 0 0 1.5708 -0 0</pose>
        <mass>0.001</mass>
        <inertia>
          <ixx>1.88079e-06</ixx>
          <ixy>0</ixy>
          <ixz>0</ixz>
          <iyy>2.00833e-06</iyy>
          <iyz>0</iyz>
          <izz>1.3912e-07</izz>
        </inertia>
      </inertial>
      <collision name='propeller_2_rightRear_link_collision'>
        <pose>0 0 0 1.5708 -0 0</pose>
        <geometry>
          <box>
            <size>0.04 0.008333 0.15</size>
          </box>
        </geometry>
      </collision>
    </link>
  <plugin name='skid_steer_drive_controller' filename='libgazebo_ros_skid_steer_drive.so'>
      <updateRate>100</updateRate>
      <robotNamespace>control/ground</robotNamespace>
      <leftFrontJoint>tire_rightFront_joint</leftFrontJoint>
      <rightFrontJoint>tire_leftFront_joint</rightFrontJoint>
      <leftRearJoint>tire_rightRear_joint</leftRearJoint>
      <rightRearJoint>tire_leftRear_joint</rightRearJoint>
      <wheelSeparation>0.16666666666666669</wheelSeparation>
      <wheelDiameter>0.1</wheelDiameter>
      <robotBaseFrame>base_link</robotBaseFrame>
      <torque>50</torque>
      <broadcastTF>1</broadcastTF>
      <commandTopic>cmd</commandTopic>
      <odometryTopic>odom</odometryTopic>
      <odometryFrame>odom</odometryFrame>
      <covariance_x>0.0001</covariance_x>
      <covariance_y>0.0001</covariance_y>
      <covariance_yaw>0.0001</covariance_yaw>
  </plugin>
    <plugin name='multirotor' filename='libgazebo_multirotor_base_plugin.so'>
      <robotNamespace/>
      <linkName>base_link</linkName>
      <rotorVelocitySlowdownSim>10</rotorVelocitySlowdownSim>
    </plugin>
    <plugin name='Rotor_leftFront_model' filename='libgazebo_motor_model.so'>
      <robotNamespace>/control/air</robotNamespace>
      <jointName>rotor_leftFront_joint</jointName>
      <linkName>rotor_leftFront_link</linkName>
      <turningDirection>ccw</turningDirection>
      <timeConstantUp>0.0125</timeConstantUp>
      <timeConstantDown>0.025</timeConstantDown>
      <maxRotVelocity>1100</maxRotVelocity>
      <motorConstant>5.84e-06</motorConstant>
      <momentConstant>0.06</momentConstant>
      <commandSubTopic>/gazebo/command/motor_speed</commandSubTopic>
      <motorNumber>2</motorNumber>
      <rotorDragCoefficient>0.000175</rotorDragCoefficient>
      <rollingMomentCoefficient>1e-06</rollingMomentCoefficient>
      <motorSpeedPubTopic>/motor_speed/0</motorSpeedPubTopic>
      <rotorVelocitySlowdownSim>50</rotorVelocitySlowdownSim>
    </plugin>
    <plugin name='Rotor_rightFront_model' filename='libgazebo_motor_model.so'>
      <robotNamespace>/control/air</robotNamespace>
      <jointName>rotor_rightFront_joint</jointName>
      <linkName>rotor_rightFront_link</linkName>
      <turningDirection>cw</turningDirection>
      <timeConstantUp>0.0125</timeConstantUp>
      <timeConstantDown>0.025</timeConstantDown>
      <maxRotVelocity>1100</maxRotVelocity>
      <motorConstant>5.84e-06</motorConstant>
      <momentConstant>0.06</momentConstant>
      <commandSubTopic>/gazebo/command/motor_speed</commandSubTopic>
      <motorNumber>0</motorNumber>
      <rotorDragCoefficient>0.000175</rotorDragCoefficient>
      <rollingMomentCoefficient>1e-06</rollingMomentCoefficient>
      <motorSpeedPubTopic>/motor_speed/0</motorSpeedPubTopic>
      <rotorVelocitySlowdownSim>50</rotorVelocitySlowdownSim>
    </plugin>
    <plugin name='Rotor_rightRear_model' filename='libgazebo_motor_model.so'>
      <robotNamespace>/control/air</robotNamespace>
      <jointName>rotor_rightRear_joint</jointName>
      <linkName>rotor_rightRear_link</linkName>
      <turningDirection>ccw</turningDirection>
      <timeConstantUp>0.0125</timeConstantUp>
      <timeConstantDown>0.025</timeConstantDown>
      <maxRotVelocity>1100</maxRotVelocity>
      <motorConstant>5.84e-06</motorConstant>
      <momentConstant>0.06</momentConstant>
      <commandSubTopic>/gazebo/command/motor_speed</commandSubTopic>
      <motorNumber>3</motorNumber>
      <rotorDragCoefficient>0.000175</rotorDragCoefficient>
      <rollingMomentCoefficient>1e-06</rollingMomentCoefficient>
      <motorSpeedPubTopic>/motor_speed/0</motorSpeedPubTopic>
      <rotorVelocitySlowdownSim>50</rotorVelocitySlowdownSim>
    </plugin>
    <plugin name='Rotor_leftRear_model' filename='libgazebo_motor_model.so'>
      <robotNamespace>/control/air</robotNamespace>
      <jointName>rotor_leftRear_joint</jointName>
      <linkName>rotor_leftRear_link</linkName>
      <turningDirection>cw</turningDirection>
      <timeConstantUp>0.0125</timeConstantUp>
      <timeConstantDown>0.025</timeConstantDown>
      <maxRotVelocity>1100</maxRotVelocity>
      <motorConstant>5.84e-06</motorConstant>
      <momentConstant>0.06</momentConstant>
      <commandSubTopic>/gazebo/command/motor_speed</commandSubTopic>
      <motorNumber>1</motorNumber>
      <rotorDragCoefficient>0.000175</rotorDragCoefficient>
      <rollingMomentCoefficient>1e-06</rollingMomentCoefficient>
      <motorSpeedPubTopic>/motor_speed/0</motorSpeedPubTopic>
      <rotorVelocitySlowdownSim>50</rotorVelocitySlowdownSim>
    </plugin>
    <plugin name='mavlink_interface' filename='libgazebo_mavlink_interface.so'>
      <robotNamespace/>
      <imuSubTopic>/imu</imuSubTopic>
      <magSubTopic>/mag</magSubTopic>
      <baroSubTopic>/baro</baroSubTopic>
      <mavlink_addr>INADDR_ANY</mavlink_addr>
      <mavlink_tcp_port>4560</mavlink_tcp_port>
      <mavlink_udp_port>14560</mavlink_udp_port>
      <serialEnabled>0</serialEnabled>
      <serialDevice>/dev/ttyACM0</serialDevice>
      <baudRate>921600</baudRate>
      <qgc_addr>INADDR_ANY</qgc_addr>
      <qgc_udp_port>14550</qgc_udp_port>
      <sdk_addr>INADDR_ANY</sdk_addr>
      <sdk_udp_port>14540</sdk_udp_port>
      <hil_mode>0</hil_mode>
      <hil_state_level>0</hil_state_level>
      <send_vision_estimation>0</send_vision_estimation>
      <send_odometry>1</send_odometry>
      <enable_lockstep>1</enable_lockstep>
      <use_tcp>1</use_tcp>
      <motorSpeedCommandPubTopic>/gazebo/command/motor_speed</motorSpeedCommandPubTopic>
      <control_channels>
        <channel name='rotor1'>
          <input_index>0</input_index>
          <input_offset>0</input_offset>
          <input_scaling>1000</input_scaling>
          <zero_position_disarmed>0</zero_position_disarmed>
          <zero_position_armed>100</zero_position_armed>
          <joint_control_type>velocity</joint_control_type>
        </channel>
        <channel name='rotor2'>
          <input_index>1</input_index>
          <input_offset>0</input_offset>
          <input_scaling>1000</input_scaling>
          <zero_position_disarmed>0</zero_position_disarmed>
          <zero_position_armed>100</zero_position_armed>
          <joint_control_type>velocity</joint_control_type>
        </channel>
        <channel name='rotor3'>
          <input_index>2</input_index>
          <input_offset>0</input_offset>
          <input_scaling>1000</input_scaling>
          <zero_position_disarmed>0</zero_position_disarmed>
          <zero_position_armed>100</zero_position_armed>
          <joint_control_type>velocity</joint_control_type>
        </channel>
        <channel name='rotor4'>
          <input_index>3</input_index>
          <input_offset>0</input_offset>
          <input_scaling>1000</input_scaling>
          <zero_position_disarmed>0</zero_position_disarmed>
          <zero_position_armed>100</zero_position_armed>
          <joint_control_type>velocity</joint_control_type>
        </channel>
        <channel name='rotor5'>
          <input_index>4</input_index>
          <input_offset>1</input_offset>
          <input_scaling>324.6</input_scaling>
          <zero_position_disarmed>0</zero_position_disarmed>
          <zero_position_armed>0</zero_position_armed>
          <joint_control_type>velocity</joint_control_type>
          <joint_control_pid>
            <p>0.1</p>
            <i>0</i>
            <d>0</d>
            <iMax>0.0</iMax>
            <iMin>0.0</iMin>
            <cmdMax>2</cmdMax>
            <cmdMin>-2</cmdMin>
          </joint_control_pid>
          <joint_name>zephyr_delta_wing::propeller_joint</joint_name>
        </channel>
        <channel name='rotor6'>
          <input_index>5</input_index>
          <input_offset>0</input_offset>
          <input_scaling>0.524</input_scaling>
          <zero_position_disarmed>0</zero_position_disarmed>
          <zero_position_armed>0</zero_position_armed>
          <joint_control_type>position</joint_control_type>
          <joint_name>zephyr_delta_wing::flap_left_joint</joint_name>
          <joint_control_pid>
            <p>10.0</p>
            <i>0</i>
            <d>0</d>
            <iMax>0</iMax>
            <iMin>0</iMin>
            <cmdMax>20</cmdMax>
            <cmdMin>-20</cmdMin>
          </joint_control_pid>
        </channel>
        <channel name='rotor7'>
          <input_index>6</input_index>
          <input_offset>0</input_offset>
          <input_scaling>0.524</input_scaling>
          <zero_position_disarmed>0</zero_position_disarmed>
          <zero_position_armed>0</zero_position_armed>
          <joint_control_type>position</joint_control_type>
          <joint_name>zephyr_delta_wing::flap_right_joint</joint_name>
          <joint_control_pid>
            <p>10.0</p>
            <i>0</i>
            <d>0</d>
            <iMax>0</iMax>
            <iMin>0</iMin>
            <cmdMax>20</cmdMax>
            <cmdMin>-20</cmdMin>
          </joint_control_pid>
        </channel>
        <channel name='rotor8'>
          <input_index>7</input_index>
          <input_offset>0</input_offset>
          <input_scaling>0.524</input_scaling>
          <zero_position_disarmed>0</zero_position_disarmed>
          <zero_position_armed>0</zero_position_armed>
          <joint_control_type>position</joint_control_type>
        </channel>
      </control_channels>
    </plugin>
   <!-- <plugin name='aerodynamics_1_rightFront_plugin' filename='libLiftDragPlugin.so'>
      <link_name>propeller_1_rightFront_link</link_name>
      <air_density>1.225</air_density>
      <area>1.0</area>
      <a0>0.1</a0>
      <cla>0.1</cla>
      <cda>0.01</cda>
      <cma>0.0</cma>
      <cp>0 -0.11375 0</cp>
      <forward>1 0 0</forward>
      <upward>0 0 1</upward>
      <alpha_stall>0.2</alpha_stall>
      <cla_stall>-0.2</cla_stall>
      <cda_stall>1.0</cda_stall>
      <cma_stall>0.0</cma_stall>
    </plugin>
    <plugin name='aerodynamics_2_rightFront_plugin' filename='libLiftDragPlugin.so'>
      <link_name>propeller_2_rightFront_link</link_name>
      <air_density>1.225</air_density>
      <area>1.0</area>
      <a0>0.1</a0>
      <cla>0.1</cla>
      <cda>0.01</cda>
      <cma>0.0</cma>
      <cp>0 0.11375 0</cp>
      <forward>-1 0 0</forward>
      <upward>0 0 1</upward>
      <alpha_stall>0.2</alpha_stall>
      <cla_stall>-0.2</cla_stall>
      <cda_stall>1.0</cda_stall>
      <cma_stall>0.0</cma_stall>
    </plugin>
    <plugin name='aerodynamics_1_leftFront_plugin' filename='libLiftDragPlugin.so'>
      <link_name>propeller_1_leftFront_link</link_name>
      <air_density>1.225</air_density>
      <area>1.0</area>
      <a0>0.1</a0>
      <cla>0.1</cla>
      <cda>0.01</cda>
      <cma>0.0</cma>
      <cp>0 -0.11375 0</cp>
      <forward>-1 0 0</forward>
      <upward>0 0 1</upward>
      <alpha_stall>0.2</alpha_stall>
      <cla_stall>-0.2</cla_stall>
      <cda_stall>1.0</cda_stall>
      <cma_stall>0.0</cma_stall>
    </plugin>
    <plugin name='aerodynamics_2_leftFront_plugin' filename='libLiftDragPlugin.so'>
      <link_name>propeller_2_leftFront_link</link_name>
      <air_density>1.225</air_density>
      <area>1.0</area>
      <a0>0.1</a0>
      <cla>0.1</cla>
      <cda>0.01</cda>
      <cma>0.0</cma>
      <cp>0 0.11375 0</cp>
      <forward>1 0 0</forward>
      <upward>0 0 1</upward>
      <alpha_stall>0.2</alpha_stall>
      <cla_stall>-0.2</cla_stall>
      <cda_stall>1.0</cda_stall>
      <cma_stall>0.0</cma_stall>
    </plugin>
    <plugin name='aerodynamics_1_rightRear_plugin' filename='libLiftDragPlugin.so'>
      <link_name>propeller_1_rightRear_link</link_name>
      <air_density>1.225</air_density>
      <area>1.0</area>
      <a0>0.1</a0>
      <cla>0.1</cla>
      <cda>0.01</cda>
      <cma>0.0</cma>
      <cp>0 -0.11375 0</cp>
      <forward>-1 0 0</forward>
      <upward>0 0 1</upward>
      <alpha_stall>0.2</alpha_stall>
      <cla_stall>-0.2</cla_stall>
      <cda_stall>1.0</cda_stall>
      <cma_stall>0.0</cma_stall>
    </plugin>
    <plugin name='aerodynamics_2_rightRear_plugin' filename='libLiftDragPlugin.so'>
      <link_name>propeller_2_rightRear_link</link_name>
      <air_density>1.225</air_density>
      <area>1.0</area>
      <a0>0.1</a0>
      <cla>0.1</cla>
      <cda>0.01</cda>
      <cma>0.0</cma>
      <cp>0 0.11375 0</cp>
      <forward>1 0 0</forward>
      <upward>0 0 1</upward>
      <alpha_stall>0.2</alpha_stall>
      <cla_stall>-0.2</cla_stall>
      <cda_stall>1.0</cda_stall>
      <cma_stall>0.0</cma_stall>
    </plugin>
    <plugin name='aerodynamics_1_leftRear_plugin' filename='libLiftDragPlugin.so'>
      <link_name>propeller_1_leftRear_link</link_name>
      <air_density>1.225</air_density>
      <area>1.0</area>
      <a0>0.1</a0>
      <cla>0.1</cla>
      <cda>0.01</cda>
      <cma>0.0</cma>
      <cp>0 -0.11375 0</cp>
      <forward>1 0 0</forward>
      <upward>0 0 1</upward>
      <alpha_stall>0.2</alpha_stall>
      <cla_stall>-0.2</cla_stall>
      <cda_stall>1.0</cda_stall>
      <cma_stall>0.0</cma_stall>
    </plugin>
    <plugin name='aerodynamics_2_leftRear_plugin' filename='libLiftDragPlugin.so'>
      <link_name>propeller_2_leftRear_link</link_name>
      <air_density>1.225</air_density>
      <area>1.0</area>
      <a0>0.1</a0>
      <cla>0.1</cla>
      <cda>0.01</cda>
      <cma>0.0</cma>
      <cp>0 0.11375 0</cp>
      <forward>-1 0 0</forward>
      <upward>0 0 1</upward>
      <alpha_stall>0.2</alpha_stall>
      <cla_stall>-0.2</cla_stall>
      <cda_stall>1.0</cda_stall>
      <cma_stall>0.0</cma_stall>
    </plugin> -->
    <frame name='FrontLeftCamera2GroundCore' attached_to='frame_link'>
      <pose>-0.25 -0.05 0.1 0 -0 3.14159</pose>
    </frame>
    <frame name='frontLeftCamera' attached_to='FrontLeftCamera2GroundCore'/>
    <frame name='FrontRightCamera2GroundCore' attached_to='frame_link'>
      <pose>-0.25 0.05 0.1 0 -0 3.14159</pose>
    </frame>
    <frame name='frontRightCamera' attached_to='FrontRightCamera2GroundCore'/>
    <frame name='FrontUltrasonic2GroundCore' attached_to='frame_link'>
      <pose>-0.13 0 0 0 -0 3.14159</pose>
    </frame>
    <frame name='frontUltrasonic' attached_to='FrontUltrasonic2GroundCore'/>
    <frame name='LeftUltrasonic2GroundCore' attached_to='frame_link'>
      <pose>-0.13 -0.075 0 0 -0 2.61799</pose>
    </frame>
    <frame name='leftUltrasonic' attached_to='LeftUltrasonic2GroundCore'/>
    <frame name='RightUltrasonic2GroundCore' attached_to='frame_link'>
      <pose>-0.13 0.075 0 0 -0 -2.618</pose>
    </frame>
    <frame name='rightUltrasonic' attached_to='RightUltrasonic2GroundCore'/>
    <frame name='axle_leftFront_joint' attached_to='frame_link'>
      <pose>0.07 0.05 -0.05 1.5708 -0 0</pose>
    </frame>
    <frame name='axle_leftFront_link' attached_to='axle_leftFront_joint'/>
    <frame name='axle_leftRear_joint' attached_to='frame_link'>
      <pose>-0.07 0.05 -0.05 1.5708 -0 0</pose>
    </frame>
    <frame name='axle_leftRear_link' attached_to='axle_leftRear_joint'/>
    <frame name='axle_rightFront_joint' attached_to='frame_link'>
      <pose>0.07 -0.05 -0.05 1.5708 -0 0</pose>
    </frame>
    <frame name='axle_rightFront_link' attached_to='axle_rightFront_joint'/>
    <frame name='axle_rightRear_joint' attached_to='frame_link'>
      <pose>-0.07 -0.05 -0.05 1.5708 -0 0</pose>
    </frame>
    <frame name='axle_rightRear_link' attached_to='axle_rightRear_joint'/>
    <frame name='stator_leftFront_joint' attached_to='frame_link'>
      <pose>0.2 0.2 0 0 -0 0</pose>
    </frame>
    <frame name='stator_leftFront_link' attached_to='stator_leftFront_joint'/>
    <frame name='stator_leftRear_joint' attached_to='frame_link'>
      <pose>-0.2 0.2 0 0 -0 0</pose>
    </frame>
    <frame name='stator_leftRear_link' attached_to='stator_leftRear_joint'/>
    <frame name='stator_rightFront_joint' attached_to='frame_link'>
      <pose>0.2 -0.2 0 0 -0 0</pose>
    </frame>
    <frame name='stator_rightFront_link' attached_to='stator_rightFront_joint'/>
    <frame name='stator_rightRear_joint' attached_to='frame_link'>
      <pose>-0.2 -0.2 0 0 -0 0</pose>
    </frame>
    <frame name='stator_rightRear_link' attached_to='stator_rightRear_joint'/>
    <frame name='visualCamera_joint' attached_to='frame_link'>
      <pose>1.2 0 0.5 0 0.2 -3.13319</pose>
    </frame>
    <frame name='visualCamera' attached_to='visualCamera_joint'/>
    <frame name='frame_joint' attached_to='base_link'>
      <pose>0 0 0 0 -0 0</pose>
    </frame>
    <frame name='frame_link' attached_to='frame_joint'/>
  </model>
</sdf>
